Workbook
Name prevWBS: a!$A1048576
Name prevWBS: b!$A1048576
Name prevWBS: 'bc 1'!$A1048576
Name prevWBS: 'c'!$A1048576
Name prevWBS: d!$A1048576
Name prevWBS: e!$A1048576
Name prevWBS: f!$A1048576
Name prevWBS: g!$A1048576
Name prevWBS: h!$A1048576
Name prevWBS: i!$A1048576
Name prevWBS: j!$A1048576
Name valuevx: 42.314159

Sheet Sheet3
A1: PIC | B1: Schedule Kirim tgl 04/03/26 | D1: Schedule Kirim tgl 03/03/26 | F1: Schedule Kirim tgl 02/03/26 | H1: Schedule Kirim tgl 20/02/26 | J1: Schedule Kirim tgl 04/02/26 | L1: Schedule Kirim tgl 02/02/26 | N1: Schedule Kirim tgl 12/01/26 | P1: Schedule Kirim tgl 09/01/26 | R1: Schedule Kirim tgl 23/12/25
C2: Days | E2: Days | G2: Days | I2: Days | K2: Days | M2: Days | O2: Days | Q2: Days
A3: Baim, Budi | B3: =+COUNTIF(i!$C$9:$C$60,Sheet3!A3) -> 7 | C3: =+SUMIF(i!$C$9:$C$60,Sheet3!A3,i!$I$9:$I$60) -> 60 | D3: =COUNTIF(h!$C$9:$C$74,Sheet3!A3) -> 7 | E3: =+SUMIF(h!$C$9:$C$74,Sheet3!A3,h!$I$9:$I$74) -> 60 | F3: =+COUNTIF(g!$C$7:$C$59,Sheet3!A3) -> 7 | G3: =+SUMIF(g!$C$7:$C$59,Sheet3!A3,g!$I$7:$I$59) -> 60 | H3: =+COUNTIF(f!$C$9:$C$59,Sheet3!A3) -> 7 | I3: =+SUMIF(f!$C$9:$C$59,Sheet3!A3,f!$I$9:$I$59) -> 61 | J3: =+COUNTIF(e!$C$9:$C$59,Sheet3!A3) -> 6 | K3: =+SUMIF(e!$C$9:$C$59,Sheet3!A3,e!$I$9:$I$59) -> 58 | L3: =+COUNTIF(d!$C$9:$C$58,Sheet3!A3) -> 6 | M3: =+SUMIF(d!$C$9:$C$58,Sheet3!A3,d!$I$9:$I$58) -> 58 | N3: =+COUNTIF(a!$D$7:$D$46,Sheet3!A3) -> 6 | O3: =+SUMIF(a!$D$7:$D$46,Sheet3!A3,a!$K$7:$K$46) -> 80 | P3: =+COUNTIF(b!$C$7:$C$46,Sheet3!A3) -> 6 | Q3: =+SUMIF(b!$C$7:$C$46,Sheet3!A3,b!$G$7:$G$46) -> 80 | R3: =+COUNTIF('c'!$C$7:$C$20,Sheet3!A3) -> 4
A4: Baim | B4: =+COUNTIF(i!$C$9:$C$60,Sheet3!A4) -> 14 | C4: =+SUMIF(i!$C$9:$C$60,Sheet3!A4,i!$I$9:$I$60) -> 44 | D4: =COUNTIF(h!$C$9:$C$74,Sheet3!A4) -> 20 | E4: =+SUMIF(h!$C$9:$C$74,Sheet3!A4,h!$I$9:$I$74) -> 60 | F4: =+COUNTIF(g!$C$7:$C$59,Sheet3!A4) -> 22 | G4: =+SUMIF(g!$C$7:$C$59,Sheet3!A4,g!$I$7:$I$59) -> 64 | H4: =+COUNTIF(f!$C$9:$C$59,Sheet3!A4) -> 23 | I4: =+SUMIF(f!$C$9:$C$59,Sheet3!A4,f!$I$9:$I$59) -> 63 | J4: =+COUNTIF(e!$C$9:$C$59,Sheet3!A4) -> 24 | K4: =+SUMIF(e!$C$9:$C$59,Sheet3!A4,e!$I$9:$I$59) -> 56 | L4: =+COUNTIF(d!$C$9:$C$58,Sheet3!A4) -> 23 | M4: =+SUMIF(d!$C$9:$C$58,Sheet3!A4,d!$I$9:$I$58) -> 54 | N4: =+COUNTIF(a!$D$7:$D$46,Sheet3!A4) -> 17 | O4: =+SUMIF(a!$D$7:$D$46,Sheet3!A4,a!$K$7:$K$46) -> 148 | P4: =+COUNTIF(b!$C$7:$C$46,Sheet3!A4) -> 16 | Q4: =+SUMIF(b!$C$7:$C$46,Sheet3!A4,b!$G$7:$G$46) -> 138 | R4: =+COUNTIF('c'!$C$7:$C$20,Sheet3!A4) -> 4
A5: Budi | B5: =+COUNTIF(i!$C$9:$C$60,Sheet3!A5) -> 15 | C5: =+SUMIF(i!$C$9:$C$60,Sheet3!A5,i!$I$9:$I$60) -> 38 | D5: =COUNTIF(h!$C$9:$C$74,Sheet3!A5) -> 19 | E5: =+SUMIF(h!$C$9:$C$74,Sheet3!A5,h!$I$9:$I$74) -> 46 | F5: =+COUNTIF(g!$C$7:$C$59,Sheet3!A5) -> 20 | G5: =+SUMIF(g!$C$7:$C$59,Sheet3!A5,g!$I$7:$I$59) -> 48 | H5: =+COUNTIF(f!$C$9:$C$59,Sheet3!A5) -> 21 | I5: =+SUMIF(f!$C$9:$C$59,Sheet3!A5,f!$I$9:$I$59) -> 47 | J5: =+COUNTIF(e!$C$9:$C$59,Sheet3!A5) -> 21 | K5: =+SUMIF(e!$C$9:$C$59,Sheet3!A5,e!$I$9:$I$59) -> 36 | L5: =+COUNTIF(d!$C$9:$C$58,Sheet3!A5) -> 21 | M5: =+SUMIF(d!$C$9:$C$58,Sheet3!A5,d!$I$9:$I$58) -> 36 | N5: =+COUNTIF(a!$D$7:$D$46,Sheet3!A5) -> 15 | O5: =+SUMIF(a!$D$7:$D$46,Sheet3!A5,a!$K$7:$K$46) -> 130 | P5: =+COUNTIF(b!$C$7:$C$46,Sheet3!A5) -> 16 | Q5: =+SUMIF(b!$C$7:$C$46,Sheet3!A5,b!$G$7:$G$46) -> 140 | R5: =+COUNTIF('c'!$C$7:$C$20,Sheet3!A5) -> 4
A6: Star | B6: =+COUNTIF(i!$C$9:$C$60,Sheet3!A6) -> 4 | C6: =+SUMIF(i!$C$9:$C$60,Sheet3!A6,i!$I$9:$I$60) -> 9 | D6: =COUNTIF(h!$C$9:$C$74,Sheet3!A6) -> 0 | E6: =+SUMIF(h!$C$9:$C$74,Sheet3!A6,h!$I$9:$I$74) -> 0 | F6: =+COUNTIF(g!$C$7:$C$59,Sheet3!A6) -> 1 | G6: =+SUMIF(g!$C$7:$C$59,Sheet3!A6,g!$I$7:$I$59) -> 3
A7: Jali | B7: =+COUNTIF(i!$C$9:$C$60,Sheet3!A7) -> 11 | C7: =+SUMIF(i!$C$9:$C$60,Sheet3!A7,i!$I$9:$I$60) -> 22 | D7: =COUNTIF(h!$C$9:$C$74,Sheet3!A7) -> 15 | E7: =+SUMIF(h!$C$9:$C$74,Sheet3!A7,h!$I$9:$I$74) -> 38 | F7: =+COUNTIF(g!$C$7:$C$59,Sheet3!A7) -> 1 | G7: =+SUMIF(g!$C$7:$C$59,Sheet3!A7,g!$I$7:$I$59) -> 3
A8: Baim/Star | B8: =+COUNTIF(i!$C$9:$C$60,Sheet3!A8) -> 0 | C8: =+SUMIF(i!$C$9:$C$60,Sheet3!A8,i!$I$9:$I$60) -> 0 | D8: =COUNTIF(h!$C$9:$C$74,Sheet3!A8) -> 2 | E8: =+SUMIF(h!$C$9:$C$74,Sheet3!A8,h!$I$9:$I$74) -> 4
A9: Budi/Star | B9: =+COUNTIF(i!$C$9:$C$60,Sheet3!A9) -> 0 | C9: =+SUMIF(i!$C$9:$C$60,Sheet3!A9,i!$I$9:$I$60) -> 0 | D9: =COUNTIF(h!$C$9:$C$74,Sheet3!A9) -> 2 | E9: =+SUMIF(h!$C$9:$C$74,Sheet3!A9,h!$I$9:$I$74) -> 4
A10: Baim/Jali | B10: =+COUNTIF(i!$C$9:$C$60,Sheet3!A10) -> 0 | C10: =+SUMIF(i!$C$9:$C$60,Sheet3!A10,i!$I$9:$I$60) -> 0 | D10: =COUNTIF(h!$C$9:$C$74,Sheet3!A10) -> 1 | E10: =+SUMIF(h!$C$9:$C$74,Sheet3!A10,h!$I$9:$I$74) -> 2
A11: Baim, Budi, Jali, Star | B11: =+COUNTIF(i!$C$9:$C$60,Sheet3!A11) -> 1 | C11: =+SUMIF(i!$C$9:$C$60,Sheet3!A11,i!$I$9:$I$60) -> 6
B13: =+SUM(B3:B11) -> 52 | C13: =+SUM(C3:C11) -> 179 | D13: =+SUM(D3:D10) -> 66 | E13: =+SUM(E3:E10) -> 214 | F13: =+SUM(F3:F7) -> 51 | G13: =+SUM(G3:G7) -> 178 | H13: =+SUM(H3:H5) -> 51 | I13: =+SUM(I3:I5) -> 171 | J13: =+SUM(J3:J5) -> 51 | K13: =+SUM(K3:K5) -> 150 | L13: =+SUM(L3:L5) -> 50 | M13: =+SUM(M3:M5) -> 148 | N13: =+SUM(N3:N5) -> 38 | O13: =+SUM(O3:O5) -> 358 | ... R13: =+SUM(R3:R5) -> 12
C14: =+SUM(i!I9:I60) -> 179 | E14: =+SUM(h!I9:I74) -> 214 | G14: =+SUM(g!I9:I59) -> 178 | I14: =+SUM(f!I9:I59) -> 171 | K14: =+SUM(e!I9:I59) -> 150 | M14: =+SUM(d!I8:I58) -> 148 | O14: =+SUM(a!K9:K46) -> 358 | Q14: =+SUM(b!G8:G46) -> 358
C15: =+C13-C14 -> 0 | E15: =+E13-E14 -> 0 | G15: =+G13-G14 -> 0 | I15: =+I13-I14 -> 0 | K15: =+K13-K14 -> 0 | M15: =+M13-M14 -> 0 | O15: =+O13-O14 -> 0 | Q15: =+Q13-Q14 -> 0

Sheet Memo
A1: No | B1: Tgl Terima Memo | C1: Memo Dari | D1: Kode Memo
A2: 1 | B2: 46078 | C2: BC | D2: 010/SL-AAA/LJ1/0226
A3: 2 | B3: 46078 | C3: BC | D3: 009/SL-OFF/LJ1/0126
A4: 3 | B4: 46093 | C4: BC | D4: 015/SL-AAA/LJ1/0326

Sheet ToDo
C1: Done | D1: =+COUNTIF(G:G,C1) -> 161 | H1: =NOW() -> 46111.338
C2: On Progres | D2: =+COUNTIF(G:G,C2) -> 0
C3: All | D3: =SUM(B:B) -> 163
A6: No | C6: Tgl | D6: Kategori | E6: Req | F6: Task | G6: Status | H6: Done Date | I6: Work Day
A7: 1 | B7: 1 | C7: 46048 | D7: SAP | F7: Belajar SAP (Custom Logic) | G7: Done | H7: 46048.373 | I7: =+H7-C7 -> 0.37346065
A8: =+A7+1 -> 2 | B8: 1 | C8: 46049 | D8: Tiket | F8: Tiket #DV-DT224000007044 | G8: Done | H8: 46049.373 | I8: =+H8-C8 -> 0.37346065
A9: =+A8+1 -> 3 | B9: 1 | C9: 46049 | D9: Tiket | F9: Tiket #DV-DT224000007053 | G9: Done | H9: 46049.373 | I9: =+H9-C9 -> 0.37346065
A10: =+A9+1 -> 4 | B10: 1 | C10: 46049 | D10: Memo | F10: Revisi Memo PO 79260003 (LJM) | G10: Done | H10: 46049.373 | I10: =+H10-C10 -> 0.37346065
A11: =+A10+1 -> 5 | B11: 1 | C11: 46049 | D11: Memo | F11: Revisi Memo PO 79704844 (LJU) | G11: Done | H11: 46049.373 | I11: =+H11-C11 -> 0.37346065
A12: =+A11+1 -> 6 | B12: 1 | C12: 46049 | D12: WA | E12: Bu Atin | F12: Ganti Material PR 399 (material Kelebihan) | G12: Done | H12: 46049.373 | I12: =+H12-C12 -> 0.37346065
A13: =+A12+1 -> 7 | B13: 1 | C13: 46049 | D13: WA | E13: Bu Atin | F13: PO 878 ganti purchase group | G13: Done | H13: 46049.373 | I13: =+H13-C13 -> 0.37346065
A14: =+A13+1 -> 8 | B14: 1 | C14: 46049 | D14: WA | E14: Sandi | F14: Upload stock Gd Packing (LJU) periode 26/01/26 | G14: Done | H14: 46049.373 | I14: =+H14-C14 -> 0.37346065
A15: =+A14+1 -> 9 | B15: 1 | C15: 46049 | D15: Telphone | E15: Ratna | F15: Revisi Harga PO 72600928 (LJU) | G15: Done | H15: 46049.373 | I15: =+H15-C15 -> 0.37346065
A16: =+A15+1 -> 10 | B16: 1 | C16: 46049 | D16: SAP | F16: Pull template PASSAP | G16: Done | H16: 46049.373 | I16: =+H16-C16 -> 0.37346065
A17: =+A16+1 -> 11 | B17: 1 | C17: 46049 | D17: WA | E17: Evi | F17: Ganti satuan BBK BG-2601-00002 | G17: Done | H17: 46049.373 | I17: =+H17-C17 -> 0.37346065
A18: =+A17+1 -> 12 | B18: 1 | C18: 46050 | D18: WA | E18: Evi | F18: Ganti satuan SJ G-2610073 | G18: Done | H18: 46050.381 | I18: =+H18-C18 -> 0.38063727
A19: =+A18+1 -> 13 | B19: 1 | C19: 46050 | D19: SAP | F19: Penambahan Modul Print Barcode Final | G19: Done | H19: 46051.376 | I19: =+H19-C19 -> 1.3756626
A20: =+A19+1 -> 14 | B20: 1 | C20: 46050 | D20: Langsung | E20: Kevin | F20: Cek PR 10260424, 10805832 | G20: Done | H20: 46050.446 | I20: =+H20-C20 -> 0.44550532
A21: =+A20+1 -> 15 | B21: 1 | C21: 46050 | D21: Telphone | E21: Bagus | F21: Menambah kolom inputan Gross Weight dan Nett Weight di modul print Invoice BC (khusus mesin) | G21: Done | H21: 46050.558 | I21: =+H21-C21 -> 0.5584331
A22: =+A21+1 -> 16 | B22: 1 | C22: 46050 | D22: Tiket | F22: Tiket #DV-DT24000006841 | G22: Done | H22: 46050.565 | I22: =+H22-C22 -> 0.56503264
A23: =+A22+1 -> 17 | B23: 1 | C23: 46050 | D23: WA | E23: Reza | F23: Revisi harga PO 78260301 (LJK) | G23: Done | H23: 46050.635 | I23: =+H23-C23 -> 0.63452836
A24: =+A23+1 -> 18 | B24: 1 | C24: 46050 | D24: WA | E24: Bu Yani | F24: Cek data Report Jasa LJU bulan Agustus 2025 web dan dekstop varian | G24: Done | H24: 46050.678 | I24: =+H24-C24 -> 0.67793889
A25: =+A24+1 -> 19 | B25: 1 | C25: 46050 | D25: WA | E25: Reza | F25: Revisi Harga PO 72600961 (LJU) | G25: Done | H25: 46050.681 | I25: =+H25-C25 -> 0.68099005
A26: =+A25+1 -> 20 | B26: 1 | C26: 46051 | D26: WA | E26: Bu Tati | F26: Ganti Alamat di Invoice 055/PI/JAN/2026 (LJU) Di Forward ke pa budi | G26: Done | H26: 46051.375 | I26: =+H26-C26 -> 0.3749184
A27: =+A26+1 -> 21 | B27: 1 | C27: 46051 | D27: SAP | F27: Diskusi Penarikan Data API dan data API Barcode SAP | G27: Done | H27: 46051.426 | I27: =+H27-C27 -> 0.42624907
A28: =+A27+1 -> 22 | B28: 1 | C28: 46051 | D28: WA | E28: Bu Tati | F28: Ganti Final Destination di Invoice 055/PI/JAN/2026 (LJU) | G28: Done | H28: 46051.464 | I28: =+H28-C28 -> 0.46413125
A29: =+A28+1 -> 23 | B29: 1 | C29: 46051 | D29: SAP | F29: Create Module Master PO template (belum tarik data) | G29: Done | H29: 46051.566 | I29: =+H29-C29 -> 0.56626111
A30: =+A29+1 -> 24 | B30: 1 | C30: 46052 | D30: WA | E30: Meris | F30: Perbaikan Sistem Puzzle LJM (material tidak bisa ditransaksikan) | G30: Done | H30: 46052.381 | I30: =+H30-C30 -> 0.380925
A31: =+A30+1 -> 25 | B31: 1 | C31: 46052 | D31: WA | E31: Evi | F31: Permintaan pembuatan SKEP : S-168/KBC.0903/2026 (LJK) | G31: Done | H31: 46052.416 | I31: =+H31-C31 -> 0.41579491
A32: =+A31+1 -> 26 | B32: 1 | C32: 46052 | D32: Langsung | E32: Taufik | F32: ganti pengkodean no aju BC30 per tgl 28 januari 2026 asal -014481- menjadi -LEC395- req pa taufik | G32: Done | H32: 46052.465 | I32: =+H32-C32 -> 0.46501817
A33: =+A32+1 -> 27 | B33: 1 | C33: 46052 | D33: WA | E33: Putri | F33: Revisi No AJU 000030-LEC395-20260127-000130 (LJU) | G33: Done | H33: 46052.564 | I33: =+H33-C33 -> 0.56405451
A34: =+A33+1 -> 28 | B34: 1 | C34: 46052 | D34: WA | E34: Bara | F34: ganti no aju BC 30 asal 25 karakter jadi 22 karakter, req bara | G34: Done | H34: 46052.573 | I34: =+H34-C34 -> 0.57300324
A35: =+A34+1 -> 29 | B35: 1 | C35: 46052 | D35: Telphone | E35: Visqia | F35: Data AJU BC25 tidak muncul di menu audit pengeluaran beacukai | G35: Done | H35: 46052.605 | I35: =+H35-C35 -> 0.60490521
A36: =+A35+1 -> 30 | B36: 1 | C36: 46053 | D36: SAP | F36: Mapping tabel untuk API Delivery(SJ) | G36: Done | H36: 46053.409 | I36: =+H36-C36 -> 0.40917037
A37: =+A36+1 -> 31 | B37: 1 | C37: 46053 | D37: SAP | F37: Buat UI penarikan data dari API dan insert data Master Delivery | G37: Done | H37: 46055.668 | I37: =+H37-C37 -> 2.6675463
A38: =+A37+1 -> 32 | B38: 1 | C38: 46053 | D38: WA | E38: Dini | F38: Cek reservasi 92603964 (LJU) material tidak muncul | G38: Done | H38: 46053.408 | I38: =+H38-C38 -> 0.40840856
A39: =+A38+1 -> 33 | B39: 1 | C39: 46053 | D39: WA | E39: Taufik | F39: hilangkan radiobuton TPB dan otomatis ceklis Ceisa di Update Dok Export BC req pa taufik | G39: Done | H39: 46053.493 | I39: =+H39-C39 -> 0.49273194
A40: =+A39+1 -> 34 | B40: 1 | C40: 46055 | D40: Tiket | F40: Tiket #DV-DT24000007117 (tunggu Memo) (diforward ke star) | G40: Done | H40: 46055.575 | I40: =+H40-C40 -> 0.57548565
A41: =+A40+1 -> 35 | B41: 1 | C41: 46055 | D41: WA | E41: Meris | F41: Cek Data Material LJK 4000051495 beda satuan | G41: Done | H41: 46055.424 | I41: =+H41-C41 -> 0.42407523
A42: =+A41+1 -> 36 | B42: 1 | C42: 46055 | D42: WA | E42: Bu Apri | F42: Cek Packing list LJK 003 (diforward ke pa budi) | G42: Done | H42: 46055.477 | I42: =+H42-C42 -> 0.47677002
...

Sheet bc 1
A1: BC(75% BC, 25% SAP)
B4: Project Start Date | C4: 46107 | G4: Display Week | H4: 1 | K4: ="Week "&(K6-($C$4-WEEKDAY($C$4,1)+2))/7+1 -> Week 1 | R4: ="Week "&(R6-($C$4-WEEKDAY($C$4,1)+2))/7+1 -> Week 2 | Y4: ="Week "&(Y6-($C$4-WEEKDAY($C$4,1)+2))/7+1 -> Week 3 | AF4: ="Week "&(AF6-($C$4-WEEKDAY($C$4,1)+2))/7+1 -> Week 4 | AM4: ="Week "&(AM6-($C$4-WEEKDAY($C$4,1)+2))/7+1 -> Week 5 | AT4: ="Week "&(AT6-($C$4-WEEKDAY($C$4,1)+2))/7+1 -> Week 6 | BA4: ="Week "&(BA6-($C$4-WEEKDAY($C$4,1)+2))/7+1 -> Week 7 | BH4: ="Week "&(BH6-($C$4-WEEKDAY($C$4,1)+2))/7+1 -> Week 8
B5: Project Lead | C5: Billy | K5: =K6 -> 46104 | R5: =R6 -> 46111 | Y5: =Y6 -> 46118 | AF5: =AF6 -> 46125 | AM5: =AM6 -> 46132 | AT5: =AT6 -> 46139 | BA5: =BA6 -> 46146 | BH5: =BH6 -> 46153
K6: =C4-WEEKDAY(C4,1)+2+7*(H4-1) -> 46104 | L6: =K6+1 -> 46105 | M6: =L6+1 -> 46106 | N6: =M6+1 -> 46107 | O6: =N6+1 -> 46108 | P6: =O6+1 -> 46109 | Q6: =P6+1 -> 46110 | R6: =Q6+1 -> 46111 | S6: =R6+1 -> 46112 | ... BN6: =BM6+1 -> 46159
A7: WBS | B7: TASK | C7: PIC | D7: MEMO | E7: START | F7: END | G7: DAYS | H7: % DONE | I7: WORK DAYS | K7: =CHOOSE(WEEKDAY(K6,1),"S","M","T","W","T","F","S") -> M | L7: =CHOOSE(WEEKDAY(L6,1),"S","M","T","W","T","F","S") -> T | M7: =CHOOSE(WEEKDAY(M6,1),"S","M","T","W","T","F","S") -> W | N7: =CHOOSE(WEEKDAY(N6,1),"S","M","T","W","T","F","S") -> T | O7: =CHOOSE(WEEKDAY(O6,1),"S","M","T","W","T","F","S") -> F | P7: =CHOOSE(WEEKDAY(P6,1),"S","M","T","W","T","F","S") -> S | Q7: =CHOOSE(WEEKDAY(Q6,1),"S","M","T","W","T","F","S") -> S | R7: =CHOOSE(WEEKDAY(R6,1),"S","M","T","W","T","F","S") -> M | ... BN7: =CHOOSE(WEEKDAY(BN6,1),"S","M","T","W","T","F","S") -> S
A8: =IF(ISERROR(VALUE(SUBSTITUTE(prevWBS,".",""))),"1",IF(ISERROR(FIND("`",SUBSTITUTE(prevWBS,".","`",1))),TEXT(VALUE(prevWBS)+1,"#"),TEXT(VALUE(LEFT(prevWBS,FIND("`",SUBSTITUTE(prevWBS,".","`",1))-1))+1,"#"))) -> 1 | B8: BC app development | F8: =IF(ISBLANK(E8)," - ",IF(G8=0,E8,E8+G8-1)) -> - | I8: =IF(OR(F8=0,E8=0)," - ",NETWORKDAYS(E8,F8)) -> -
A9: =IF(ISERROR(VALUE(SUBSTITUTE(prevWBS,".",""))),"0.1",IF(ISERROR(FIND("`",SUBSTITUTE(prevWBS,".","`",1))),prevWBS&".1",LEFT(prevWBS,FIND("`",SUBSTITUTE(prevWBS,".","`",1)))&IF(ISERROR(FIND("`",SUBSTITUTE(prevWBS,".","`",2))),VALUE(RIGHT(prevWBS,LEN(prevWBS)-FIND("`",SUBSTITUTE(prevWBS,".","`",1))))+1,VALUE(MID(prevWBS,FIND("`",SUBSTITUTE(prevWBS,".","`",1))+1,(FIND("`",SUBSTITUTE(prevWBS,".","`",2))-FIND("`",SUBSTITUTE(prevWBS,".","`",1))-1)))+1))) -> 1.1 | B9: Menu Beacukai, Sub Menu Update Dok Keluar Market, Form Traceability Belum Ada Di MCS LJK [http://192.168.255.84/pzzl/index.php/Legal/updateKeluar2] | C9: Baim | D9: 015/SL-AAA/LJ1/0326 | E9: 46107 | F9: =IF(ISBLANK(E9)," - ",IF(G9=0,E9,E9+G9-1)) -> 46107 | G9: 1 | H9: 1 | I9: =IF(OR(F9=0,E9=0)," - ",NETWORKDAYS(E9,F9)) -> 1
A10: =IF(ISERROR(VALUE(SUBSTITUTE(prevWBS,".",""))),"0.1",IF(ISERROR(FIND("`",SUBSTITUTE(prevWBS,".","`",1))),prevWBS&".1",LEFT(prevWBS,FIND("`",SUBSTITUTE(prevWBS,".","`",1)))&IF(ISERROR(FIND("`",SUBSTITUTE(prevWBS,".","`",2))),VALUE(RIGHT(prevWBS,LEN(prevWBS)-FIND("`",SUBSTITUTE(prevWBS,".","`",1))))+1,VALUE(MID(prevWBS,FIND("`",SUBSTITUTE(prevWBS,".","`",1))+1,(FIND("`",SUBSTITUTE(prevWBS,".","`",2))-FIND("`",SUBSTITUTE(prevWBS,".","`",1))-1)))+1))) -> 1.2 | B10: Menu Beacukai, Sub Menu Update Dok Non-Keluar Market, Form Traceability Belum Ada Di MCS LJK[http://192.168.255.84/pzzl/index.php/Legal/updateKeluar] | C10: Baim | D10: 015/SL-AAA/LJ1/0326 | E10: 46107 | F10: =IF(ISBLANK(E10)," - ",IF(G10=0,E10,E10+G10-1)) -> 46107 | G10: 1 | H10: 1 | I10: =IF(OR(F10=0,E10=0)," - ",NETWORKDAYS(E10,F10)) -> 1
A11: =IF(ISERROR(VALUE(SUBSTITUTE(prevWBS,".",""))),"0.1",IF(ISERROR(FIND("`",SUBSTITUTE(prevWBS,".","`",1))),prevWBS&".1",LEFT(prevWBS,FIND("`",SUBSTITUTE(prevWBS,".","`",1)))&IF(ISERROR(FIND("`",SUBSTITUTE(prevWBS,".","`",2))),VALUE(RIGHT(prevWBS,LEN(prevWBS)-FIND("`",SUBSTITUTE(prevWBS,".","`",1))))+1,VALUE(MID(prevWBS,FIND("`",SUBSTITUTE(prevWBS,".","`",1))+1,(FIND("`",SUBSTITUTE(prevWBS,".","`",2))-FIND("`",SUBSTITUTE(prevWBS,".","`",1))-1)))+1))) -> 1.3 | B11: Menu Laporan Keluar/Masuk, Sub Menu Balance Lokal Belum Ada Di MCS LJK[http://192.168.255.84/pzzl/index.php/Legal/balancing\_local] | C11: Baim | D11: 015/SL-AAA/LJ1/0326 | E11: 46108 | F11: =IF(ISBLANK(E11)," - ",IF(G11=0,E11,E11+G11-1)) -> 46108 | G11: 1 | H11: 1 | I11: =IF(OR(F11=0,E11=0)," - ",NETWORKDAYS(E11,F11)) -> 1
A12: =IF(ISERROR(VALUE(SUBSTITUTE(prevWBS,".",""))),"0.1",IF(ISERROR(FIND("`",SUBSTITUTE(prevWBS,".","`",1))),prevWBS&".1",LEFT(prevWBS,FIND("`",SUBSTITUTE(prevWBS,".","`",1)))&IF(ISERROR(FIND("`",SUBSTITUTE(prevWBS,".","`",2))),VALUE(RIGHT(prevWBS,LEN(prevWBS)-FIND("`",SUBSTITUTE(prevWBS,".","`",1))))+1,VALUE(MID(prevWBS,FIND("`",SUBSTITUTE(prevWBS,".","`",1))+1,(FIND("`",SUBSTITUTE(prevWBS,".","`",2))-FIND("`",SUBSTITUTE(prevWBS,".","`",1))-1)))+1))) -> 1.4 | B12: Menu Print, Sub menu Packing List Dan Invoice Belum Ada Di MCS LJK [http://192.168.255.84/pzzl/index.php/Legal/packingListInvoice] | C12: Baim | D12: 015/SL-AAA/LJ1/0326 | E12: 46109 | F12: =IF(ISBLANK(E12)," - ",IF(G12=0,E12,E12+G12-1)) -> 46111 | G12: 3 | H12: 1 | I12: =IF(OR(F12=0,E12=0)," - ",NETWORKDAYS(E12,F12)) -> 1
A13: =IF(ISERROR(VALUE(SUBSTITUTE(prevWBS,".",""))),"0.1",IF(ISERROR(FIND("`",SUBSTITUTE(prevWBS,".","`",1))),prevWBS&".1",LEFT(prevWBS,FIND("`",SUBSTITUTE(prevWBS,".","`",1)))&IF(ISERROR(FIND("`",SUBSTITUTE(prevWBS,".","`",2))),VALUE(RIGHT(prevWBS,LEN(prevWBS)-FIND("`",SUBSTITUTE(prevWBS,".","`",1))))+1,VALUE(MID(prevWBS,FIND("`",SUBSTITUTE(prevWBS,".","`",1))+1,(FIND("`",SUBSTITUTE(prevWBS,".","`",2))-FIND("`",SUBSTITUTE(prevWBS,".","`",1))-1)))+1))) -> 1.5 | B13: Menu Mutasi, Sub menu Bahan Bakar Belum Ada Di IT INVENTORY LJK[http://192.168.255.84/leuwitex/beacukai/rMutBBM] | C13: Baim | D13: 015/SL-AAA/LJ1/0326 | E13: 46111 | F13: =IF(ISBLANK(E13)," - ",IF(G13=0,E13,E13+G13-1)) -> 46111 | G13: 1 | H13: 0 | I13: =IF(OR(F13=0,E13=0)," - ",NETWORKDAYS(E13,F13)) -> 1
A14: =IF(ISERROR(VALUE(SUBSTITUTE(prevWBS,".",""))),"0.1",IF(ISERROR(FIND("`",SUBSTITUTE(prevWBS,".","`",1))),prevWBS&".1",LEFT(prevWBS,FIND("`",SUBSTITUTE(prevWBS,".","`",1)))&IF(ISERROR(FIND("`",SUBSTITUTE(prevWBS,".","`",2))),VALUE(RIGHT(prevWBS,LEN(prevWBS)-FIND("`",SUBSTITUTE(prevWBS,".","`",1))))+1,VALUE(MID(prevWBS,FIND("`",SUBSTITUTE(prevWBS,".","`",1))+1,(FIND("`",SUBSTITUTE(prevWBS,".","`",2))-FIND("`",SUBSTITUTE(prevWBS,".","`",1))-1)))+1))) -> 1.6 | B14: 1a Menambah kolom : Asal Doc , No Daftar dan Tanggal daftar(/pzzl/index.php/Warehouse/laporanKeluar) | C14: Baim | D14: 142/ML-OFF/LJ1/1125 | E14: 46112 | F14: =IF(ISBLANK(E14)," - ",IF(G14=0,E14,E14+G14-1)) -> 46112 | G14: 1 | H14: 0 | I14: =IF(OR(F14=0,E14=0)," - ",NETWORKDAYS(E14,F14)) -> 1
A15: =IF(ISERROR(VALUE(SUBSTITUTE(prevWBS,".",""))),"0.1",IF(ISERROR(FIND("`",SUBSTITUTE(prevWBS,".","`",1))),prevWBS&".1",LEFT(prevWBS,FIND("`",SUBSTITUTE(prevWBS,".","`",1)))&IF(ISERROR(FIND("`",SUBSTITUTE(prevWBS,".","`",2))),VALUE(RIGHT(prevWBS,LEN(prevWBS)-FIND("`",SUBSTITUTE(prevWBS,".","`",1))))+1,VALUE(MID(prevWBS,FIND("`",SUBSTITUTE(prevWBS,".","`",1))+1,(FIND("`",SUBSTITUTE(prevWBS,".","`",2))-FIND("`",SUBSTITUTE(prevWBS,".","`",1))-1)))+1))) -> 1.7 | B15: 1b Menambah menu Edit untuk Pengisian Asal DOC, No Daftar dan Tanggal Daftar(/pzzl/index.php/Warehouse/laporanMasuk) | C15: Baim | D15: 142/ML-OFF/LJ1/1125 | E15: 46113 | F15: =IF(ISBLANK(E15)," - ",IF(G15=0,E15,E15+G15-1)) -> 46113 | G15: 1 | H15: 0 | I15: =IF(OR(F15=0,E15=0)," - ",NETWORKDAYS(E15,F15)) -> 1
A16: =IF(ISERROR(VALUE(SUBSTITUTE(prevWBS,".",""))),"0.1",IF(ISERROR(FIND("`",SUBSTITUTE(prevWBS,".","`",1))),prevWBS&".1",LEFT(prevWBS,FIND("`",SUBSTITUTE(prevWBS,".","`",1)))&IF(ISERROR(FIND("`",SUBSTITUTE(prevWBS,".","`",2))),VALUE(RIGHT(prevWBS,LEN(prevWBS)-FIND("`",SUBSTITUTE(prevWBS,".","`",1))))+1,VALUE(MID(prevWBS,FIND("`",SUBSTITUTE(prevWBS,".","`",1))+1,(FIND("`",SUBSTITUTE(prevWBS,".","`",2))-FIND("`",SUBSTITUTE(prevWBS,".","`",1))-1)))+1))) -> 1.8 | B16: 2 Belum tersedia untuk user LJK(/pzzl/index.php/MIT/dashboard) | C16: Baim | D16: 142/ML-OFF/LJ1/1125 | E16: 46114 | F16: =IF(ISBLANK(E16)," - ",IF(G16=0,E16,E16+G16-1)) -> 46114 | G16: 1 | H16: 0 | I16: =IF(OR(F16=0,E16=0)," - ",NETWORKDAYS(E16,F16)) -> 1
A17: =IF(ISERROR(VALUE(SUBSTITUTE(prevWBS,".",""))),"0.1",IF(ISERROR(FIND("`",SUBSTITUTE(prevWBS,".","`",1))),prevWBS&".1",LEFT(prevWBS,FIND("`",SUBSTITUTE(prevWBS,".","`",1)))&IF(ISERROR(FIND("`",SUBSTITUTE(prevWBS,".","`",2))),VALUE(RIGHT(prevWBS,LEN(prevWBS)-FIND("`",SUBSTITUTE(prevWBS,".","`",1))))+1,VALUE(MID(prevWBS,FIND("`",SUBSTITUTE(prevWBS,".","`",1))+1,(FIND("`",SUBSTITUTE(prevWBS,".","`",2))-FIND("`",SUBSTITUTE(prevWBS,".","`",1))-1)))+1))) -> 1.9 | B17: 3a penambahan kolom dengan nama QTY Keluar Tunggu Doc BC(/pzzl/index.php/Reporting/reportMR) | C17: Baim | D17: 142/ML-OFF/LJ1/1125 | E17: 46115 | F17: =IF(ISBLANK(E17)," - ",IF(G17=0,E17,E17+G17-1)) -> 46115 | G17: 1 | H17: 0 | I17: =IF(OR(F17=0,E17=0)," - ",NETWORKDAYS(E17,F17)) -> 1
A18: =IF(ISERROR(VALUE(SUBSTITUTE(prevWBS,".",""))),"0.1",IF(ISERROR(FIND("`",SUBSTITUTE(prevWBS,".","`",1))),prevWBS&".1",LEFT(prevWBS,FIND("`",SUBSTITUTE(prevWBS,".","`",1)))&IF(ISERROR(FIND("`",SUBSTITUTE(prevWBS,".","`",2))),VALUE(RIGHT(prevWBS,LEN(prevWBS)-FIND("`",SUBSTITUTE(prevWBS,".","`",1))))+1,VALUE(MID(prevWBS,FIND("`",SUBSTITUTE(prevWBS,".","`",1))+1,(FIND("`",SUBSTITUTE(prevWBS,".","`",2))-FIND("`",SUBSTITUTE(prevWBS,".","`",1))-1)))+1))) -> 1.10 | B18: 3b saldo buku belum berkurang jika doc bc belum terupdate(/pzzl/index.php/Reporting/reportMR) | C18: Baim | D18: 142/ML-OFF/LJ1/1125 | E18: 46116 | F18: =IF(ISBLANK(E18)," - ",IF(G18=0,E18,E18+G18-1)) -> 46116 | G18: 1 | H18: 0 | I18: =IF(OR(F18=0,E18=0)," - ",NETWORKDAYS(E18,F18)) -> 0
A19: =IF(ISERROR(VALUE(SUBSTITUTE(prevWBS,".",""))),"0.1",IF(ISERROR(FIND("`",SUBSTITUTE(prevWBS,".","`",1))),prevWBS&".1",LEFT(prevWBS,FIND("`",SUBSTITUTE(prevWBS,".","`",1)))&IF(ISERROR(FIND("`",SUBSTITUTE(prevWBS,".","`",2))),VALUE(RIGHT(prevWBS,LEN(prevWBS)-FIND("`",SUBSTITUTE(prevWBS,".","`",1))))+1,VALUE(MID(prevWBS,FIND("`",SUBSTITUTE(prevWBS,".","`",1))+1,(FIND("`",SUBSTITUTE(prevWBS,".","`",2))-FIND("`",SUBSTITUTE(prevWBS,".","`",1))-1)))+1))) -> 1.11 | B19: 4 Laporan mutasi yg muncul sesuai dengan user yang digunakan(/pzzl/index.php/Reporting/reportMR) | C19: Baim | D19: 142/ML-OFF/LJ1/1125 | E19: 46117 | F19: =IF(ISBLANK(E19)," - ",IF(G19=0,E19,E19+G19-1)) -> 46117 | G19: 1 | H19: 0 | I19: =IF(OR(F19=0,E19=0)," - ",NETWORKDAYS(E19,F19)) -> 0
A76: =IF(ISERROR(VALUE(SUBSTITUTE(prevWBS,".",""))),"1",IF(ISERROR(FIND("`",SUBSTITUTE(prevWBS,".","`",1))),TEXT(VALUE(prevWBS)+1,"#"),TEXT(VALUE(LEFT(prevWBS,FIND("`",SUBSTITUTE(prevWBS,".","`",1))-1))+1,"#"))) -> 1 | B76: Report | F76: =IF(ISBLANK(E76)," - ",IF(G76=0,E76,E76+G76-1)) -> - | I76: =IF(OR(F76=0,E76=0)," - ",NETWORKDAYS(E76,F76)) -> -
A77: =IF(ISERROR(VALUE(SUBSTITUTE(prevWBS,".",""))),"0.1",IF(ISERROR(FIND("`",SUBSTITUTE(prevWBS,".","`",1))),prevWBS&".1",LEFT(prevWBS,FIND("`",SUBSTITUTE(prevWBS,".","`",1)))&IF(ISERROR(FIND("`",SUBSTITUTE(prevWBS,".","`",2))),VALUE(RIGHT(prevWBS,LEN(prevWBS)-FIND("`",SUBSTITUTE(prevWBS,".","`",1))))+1,VALUE(MID(prevWBS,FIND("`",SUBSTITUTE(prevWBS,".","`",1))+1,(FIND("`",SUBSTITUTE(prevWBS,".","`",2))-FIND("`",SUBSTITUTE(prevWBS,".","`",1))-1)))+1))) -> 1.1 | B77: REPORT - WM - MOVING HISTORY - GUDANG GREY | C77: Billy, Baim | E77: 46057 | F77: =IF(ISBLANK(E77)," - ",IF(G77=0,E77,E77+G77-1)) -> 46063 | G77: 7 | H77: 0 | I77: =IF(OR(F77=0,E77=0)," - ",NETWORKDAYS(E77,F77)) -> 5
A78: =IF(ISERROR(VALUE(SUBSTITUTE(prevWBS,".",""))),"0.1",IF(ISERROR(FIND("`",SUBSTITUTE(prevWBS,".","`",1))),prevWBS&".1",LEFT(prevWBS,FIND("`",SUBSTITUTE(prevWBS,".","`",1)))&IF(ISERROR(FIND("`",SUBSTITUTE(prevWBS,".","`",2))),VALUE(RIGHT(prevWBS,LEN(prevWBS)-FIND("`",SUBSTITUTE(prevWBS,".","`",1))))+1,VALUE(MID(prevWBS,FIND("`",SUBSTITUTE(prevWBS,".","`",1))+1,(FIND("`",SUBSTITUTE(prevWBS,".","`",2))-FIND("`",SUBSTITUTE(prevWBS,".","`",1))-1)))+1))) -> 1.2 | B78: REPORT - WM - STOCK PER BARCODE | C78: Baim | E78: 46064 | F78: =IF(ISBLANK(E78)," - ",IF(G78=0,E78,E78+G78-1)) -> 46070 | G78: 7 | H78: 0 | I78: =IF(OR(F78=0,E78=0)," - ",NETWORKDAYS(E78,F78)) -> 5
A79: =IF(ISERROR(VALUE(SUBSTITUTE(prevWBS,".",""))),"0.1",IF(ISERROR(FIND("`",SUBSTITUTE(prevWBS,".","`",1))),prevWBS&".1",LEFT(prevWBS,FIND("`",SUBSTITUTE(prevWBS,".","`",1)))&IF(ISERROR(FIND("`",SUBSTITUTE(prevWBS,".","`",2))),VALUE(RIGHT(prevWBS,LEN(prevWBS)-FIND("`",SUBSTITUTE(prevWBS,".","`",1))))+1,VALUE(MID(prevWBS,FIND("`",SUBSTITUTE(prevWBS,".","`",1))+1,(FIND("`",SUBSTITUTE(prevWBS,".","`",2))-FIND("`",SUBSTITUTE(prevWBS,".","`",1))-1)))+1))) -> 1.3 | B79: REPORT - WM - LAPORAN PERSEDIAAN GUDANG PACKING | C79: Budi | E79: 46064 | F79: =IF(ISBLANK(E79)," - ",IF(G79=0,E79,E79+G79-1)) -> 46070 | G79: 7 | H79: 0 | I79: =IF(OR(F79=0,E79=0)," - ",NETWORKDAYS(E79,F79)) -> 5
A80: =IF(ISERROR(VALUE(SUBSTITUTE(prevWBS,".",""))),"0.1",IF(ISERROR(FIND("`",SUBSTITUTE(prevWBS,".","`",1))),prevWBS&".1",LEFT(prevWBS,FIND("`",SUBSTITUTE(prevWBS,".","`",1)))&IF(ISERROR(FIND("`",SUBSTITUTE(prevWBS,".","`",2))),VALUE(RIGHT(prevWBS,LEN(prevWBS)-FIND("`",SUBSTITUTE(prevWBS,".","`",1))))+1,VALUE(MID(prevWBS,FIND("`",SUBSTITUTE(prevWBS,".","`",1))+1,(FIND("`",SUBSTITUTE(prevWBS,".","`",2))-FIND("`",SUBSTITUTE(prevWBS,".","`",1))-1)))+1))) -> 1.4 | B80: REPORT - WM - LAPORAN GUDANG PACKING LEAD TIME | C80: Baim | E80: 46071 | F80: =IF(ISBLANK(E80)," - ",IF(G80=0,E80,E80+G80-1)) -> 46077 | G80: 7 | H80: 0 | I80: =IF(OR(F80=0,E80=0)," - ",NETWORKDAYS(E80,F80)) -> 5
A81: =IF(ISERROR(VALUE(SUBSTITUTE(prevWBS,".",""))),"0.1",IF(ISERROR(FIND("`",SUBSTITUTE(prevWBS,".","`",1))),prevWBS&".1",LEFT(prevWBS,FIND("`",SUBSTITUTE(prevWBS,".","`",1)))&IF(ISERROR(FIND("`",SUBSTITUTE(prevWBS,".","`",2))),VALUE(RIGHT(prevWBS,LEN(prevWBS)-FIND("`",SUBSTITUTE(prevWBS,".","`",1))))+1,VALUE(MID(prevWBS,FIND("`",SUBSTITUTE(prevWBS,".","`",1))+1,(FIND("`",SUBSTITUTE(prevWBS,".","`",2))-FIND("`",SUBSTITUTE(prevWBS,".","`",1))-1)))+1))) -> 1.5 | B81: REPORT - WM - LIST KARTON PER KODE ORDER | C81: Budi | E81: 46071 | F81: =IF(ISBLANK(E81)," - ",IF(G81=0,E81,E81+G81-1)) -> 46077 | G81: 7 | H81: 0 | I81: =IF(OR(F81=0,E81=0)," - ",NETWORKDAYS(E81,F81)) -> 5
A82: =IF(ISERROR(VALUE(SUBSTITUTE(prevWBS,".",""))),"0.1",IF(ISERROR(FIND("`",SUBSTITUTE(prevWBS,".","`",1))),prevWBS&".1",LEFT(prevWBS,FIND("`",SUBSTITUTE(prevWBS,".","`",1)))&IF(ISERROR(FIND("`",SUBSTITUTE(prevWBS,".","`",2))),VALUE(RIGHT(prevWBS,LEN(prevWBS)-FIND("`",SUBSTITUTE(prevWBS,".","`",1))))+1,VALUE(MID(prevWBS,FIND("`",SUBSTITUTE(prevWBS,".","`",1))+1,(FIND("`",SUBSTITUTE(prevWBS,".","`",2))-FIND("`",SUBSTITUTE(prevWBS,".","`",1))-1)))+1))) -> 1.6 | B82: REPORT - WM - MOVING HISTORY PER BARCODE | C82: Baim | E82: 46078 | F82: =IF(ISBLANK(E82)," - ",IF(G82=0,E82,E82+G82-1)) -> 46084 | G82: 7 | H82: 0 | I82: =IF(OR(F82=0,E82=0)," - ",NETWORKDAYS(E82,F82)) -> 5
A83: =IF(ISERROR(VALUE(SUBSTITUTE(prevWBS,".",""))),"0.1",IF(ISERROR(FIND("`",SUBSTITUTE(prevWBS,".","`",1))),prevWBS&".1",LEFT(prevWBS,FIND("`",SUBSTITUTE(prevWBS,".","`",1)))&IF(ISERROR(FIND("`",SUBSTITUTE(prevWBS,".","`",2))),VALUE(RIGHT(prevWBS,LEN(prevWBS)-FIND("`",SUBSTITUTE(prevWBS,".","`",1))))+1,VALUE(MID(prevWBS,FIND("`",SUBSTITUTE(prevWBS,".","`",1))+1,(FIND("`",SUBSTITUTE(prevWBS,".","`",2))-FIND("`",SUBSTITUTE(prevWBS,".","`",1))-1)))+1))) -> 1.7 | B83: REPORT - WM - MOVING HISTORY PER LIST KARTON | C83: Budi | E83: 46078 | F83: =IF(ISBLANK(E83)," - ",IF(G83=0,E83,E83+G83-1)) -> 46084 | G83: 7 | H83: 0 | I83: =IF(OR(F83=0,E83=0)," - ",NETWORKDAYS(E83,F83)) -> 5
A84: =IF(ISERROR(VALUE(SUBSTITUTE(prevWBS,".",""))),"0.1",IF(ISERROR(FIND("`",SUBSTITUTE(prevWBS,".","`",1))),prevWBS&".1",LEFT(prevWBS,FIND("`",SUBSTITUTE(prevWBS,".","`",1)))&IF(ISERROR(FIND("`",SUBSTITUTE(prevWBS,".","`",2))),VALUE(RIGHT(prevWBS,LEN(prevWBS)-FIND("`",SUBSTITUTE(prevWBS,".","`",1))))+1,VALUE(MID(prevWBS,FIND("`",SUBSTITUTE(prevWBS,".","`",1))+1,(FIND("`",SUBSTITUTE(prevWBS,".","`",2))-FIND("`",SUBSTITUTE(prevWBS,".","`",1))-1)))+1))) -> 1.8 | B84: REPORT - MM - STOCK KAIN GREY (GRADE) | C84: Billy, Budi | E84: 46057 | F84: =IF(ISBLANK(E84)," - ",IF(G84=0,E84,E84+G84-1)) -> 46063 | G84: 7 | H84: 0 | I84: =IF(OR(F84=0,E84=0)," - ",NETWORKDAYS(E84,F84)) -> 5
A85: =IF(ISERROR(VALUE(SUBSTITUTE(prevWBS,".",""))),"0.1",IF(ISERROR(FIND("`",SUBSTITUTE(prevWBS,".","`",1))),prevWBS&".1",LEFT(prevWBS,FIND("`",SUBSTITUTE(prevWBS,".","`",1)))&IF(ISERROR(FIND("`",SUBSTITUTE(prevWBS,".","`",2))),VALUE(RIGHT(prevWBS,LEN(prevWBS)-FIND("`",SUBSTITUTE(prevWBS,".","`",1))))+1,VALUE(MID(prevWBS,FIND("`",SUBSTITUTE(prevWBS,".","`",1))+1,(FIND("`",SUBSTITUTE(prevWBS,".","`",2))-FIND("`",SUBSTITUTE(prevWBS,".","`",1))-1)))+1))) -> 1.9 | B85: REPORT - MM - STOCK LEADTIME | C85: Baim | E85: 46085 | F85: =IF(ISBLANK(E85)," - ",IF(G85=0,E85,E85+G85-1)) -> 46091 | G85: 7 | H85: 0 | I85: =IF(OR(F85=0,E85=0)," - ",NETWORKDAYS(E85,F85)) -> 5
A86: =IF(ISERROR(VALUE(SUBSTITUTE(prevWBS,".",""))),"0.1",IF(ISERROR(FIND("`",SUBSTITUTE(prevWBS,".","`",1))),prevWBS&".1",LEFT(prevWBS,FIND("`",SUBSTITUTE(prevWBS,".","`",1)))&IF(ISERROR(FIND("`",SUBSTITUTE(prevWBS,".","`",2))),VALUE(RIGHT(prevWBS,LEN(prevWBS)-FIND("`",SUBSTITUTE(prevWBS,".","`",1))))+1,VALUE(MID(prevWBS,FIND("`",SUBSTITUTE(prevWBS,".","`",1))+1,(FIND("`",SUBSTITUTE(prevWBS,".","`",2))-FIND("`",SUBSTITUTE(prevWBS,".","`",1))-1)))+1))) -> 1.10 | B86: REPORT - MM - STOCK GREY LEAD TIME PER GRADE | C86: Budi | E86: 46085 | F86: =IF(ISBLANK(E86)," - ",IF(G86=0,E86,E86+G86-1)) -> 46091 | G86: 7 | H86: 0 | I86: =IF(OR(F86=0,E86=0)," - ",NETWORKDAYS(E86,F86)) -> 5
A87: =IF(ISERROR(VALUE(SUBSTITUTE(prevWBS,".",""))),"0.1",IF(ISERROR(FIND("`",SUBSTITUTE(prevWBS,".","`",1))),prevWBS&".1",LEFT(prevWBS,FIND("`",SUBSTITUTE(prevWBS,".","`",1)))&IF(ISERROR(FIND("`",SUBSTITUTE(prevWBS,".","`",2))),VALUE(RIGHT(prevWBS,LEN(prevWBS)-FIND("`",SUBSTITUTE(prevWBS,".","`",1))))+1,VALUE(MID(prevWBS,FIND("`",SUBSTITUTE(prevWBS,".","`",1))+1,(FIND("`",SUBSTITUTE(prevWBS,".","`",2))-FIND("`",SUBSTITUTE(prevWBS,".","`",1))-1)))+1))) -> 1.11 | B87: REPORT - MM - STOCK BALANCE KAIN GREY | C87: Budi | E87: 46092 | F87: =IF(ISBLANK(E87)," - ",IF(G87=0,E87,E87+G87-1)) -> 46098 | G87: 7 | H87: 0 | I87: =IF(OR(F87=0,E87=0)," - ",NETWORKDAYS(E87,F87)) -> 5
A88: =IF(ISERROR(VALUE(SUBSTITUTE(prevWBS,".",""))),"0.1",IF(ISERROR(FIND("`",SUBSTITUTE(prevWBS,".","`",1))),prevWBS&".1",LEFT(prevWBS,FIND("`",SUBSTITUTE(prevWBS,".","`",1)))&IF(ISERROR(FIND("`",SUBSTITUTE(prevWBS,".","`",2))),VALUE(RIGHT(prevWBS,LEN(prevWBS)-FIND("`",SUBSTITUTE(prevWBS,".","`",1))))+1,VALUE(MID(prevWBS,FIND("`",SUBSTITUTE(prevWBS,".","`",1))+1,(FIND("`",SUBSTITUTE(prevWBS,".","`",2))-FIND("`",SUBSTITUTE(prevWBS,".","`",1))-1)))+1))) -> 1.12 | B88: REPORT - MM - STOCK KAIN PASIF (ALL AREA) | C88: Baim | E88: 46092 | F88: =IF(ISBLANK(E88)," - ",IF(G88=0,E88,E88+G88-1)) -> 46098 | G88: 7 | H88: 0 | I88: =IF(OR(F88=0,E88=0)," - ",NETWORKDAYS(E88,F88)) -> 5
... A103: =IF(ISERROR(VALUE(SUBSTITUTE(prevWBS,".",""))),"0.1",IF(ISERROR(FIND("`",SUBSTITUTE(prevWBS,".","`",1))),prevWBS&".1",LEFT(prevWBS,FIND("`",SUBSTITUTE(prevWBS,".","`",1)))&IF(ISERROR(FIND("`",SUBSTITUTE(prevWBS,".","`",2))),VALUE(RIGHT(prevWBS,LEN(prevWBS)-FIND("`",SUBSTITUTE(prevWBS,".","`",1))))+1,VALUE(MID(prevWBS,FIND("`",SUBSTITUTE(prevWBS,".","`",1))+1,(FIND("`",SUBSTITUTE(prevWBS,".","`",2))-FIND("`",SUBSTITUTE(prevWBS,".","`",1))-1)))+1))) -> 1.27 | B103: REPORT - MM - STK Blank Gd. Packing | C103: Budi | E103: 46148 | F103: =IF(ISBLANK(E103)," - ",IF(G103=0,E103,E103+G103-1)) -> 46154 | G103: 7 | H103: 0 | I103: =IF(OR(F103=0,E103=0)," - ",NETWORKDAYS(E103,F103)) -> 5
A104: =IF(ISERROR(VALUE(SUBSTITUTE(prevWBS,".",""))),"1",IF(ISERROR(FIND("`",SUBSTITUTE(prevWBS,".","`",1))),TEXT(VALUE(prevWBS)+1,"#"),TEXT(VALUE(LEFT(prevWBS,FIND("`",SUBSTITUTE(prevWBS,".","`",1))-1))+1,"#"))) -> 2 | B104: Interfaces | F104: =IF(ISBLANK(E104)," - ",IF(G104=0,E104,E104+G104-1)) -> - | I104: =IF(OR(F104=0,E104=0)," - ",NETWORKDAYS(E104,F104)) -> -
A105: =IF(ISERROR(VALUE(SUBSTITUTE(prevWBS,".",""))),"0.1",IF(ISERROR(FIND("`",SUBSTITUTE(prevWBS,".","`",1))),prevWBS&".1",LEFT(prevWBS,FIND("`",SUBSTITUTE(prevWBS,".","`",1)))&IF(ISERROR(FIND("`",SUBSTITUTE(prevWBS,".","`",2))),VALUE(RIGHT(prevWBS,LEN(prevWBS)-FIND("`",SUBSTITUTE(prevWBS,".","`",1))))+1,VALUE(MID(prevWBS,FIND("`",SUBSTITUTE(prevWBS,".","`",1))+1,(FIND("`",SUBSTITUTE(prevWBS,".","`",2))-FIND("`",SUBSTITUTE(prevWBS,".","`",1))-1)))+1))) -> 2.1 | B105: INTERFACE BEA CUKAI | C105: Billy, Budi | E105: 46034 | F105: =IF(ISBLANK(E105)," - ",IF(G105=0,E105,E105+G105-1)) -> 46038 | G105: 5 | H105: 0 | I105: =IF(OR(F105=0,E105=0)," - ",NETWORKDAYS(E105,F105)) -> 5
A106: =IF(ISERROR(VALUE(SUBSTITUTE(prevWBS,".",""))),"0.1",IF(ISERROR(FIND("`",SUBSTITUTE(prevWBS,".","`",1))),prevWBS&".1",LEFT(prevWBS,FIND("`",SUBSTITUTE(prevWBS,".","`",1)))&IF(ISERROR(FIND("`",SUBSTITUTE(prevWBS,".","`",2))),VALUE(RIGHT(prevWBS,LEN(prevWBS)-FIND("`",SUBSTITUTE(prevWBS,".","`",1))))+1,VALUE(MID(prevWBS,FIND("`",SUBSTITUTE(prevWBS,".","`",1))+1,(FIND("`",SUBSTITUTE(prevWBS,".","`",2))-FIND("`",SUBSTITUTE(prevWBS,".","`",1))-1)))+1))) -> 2.2 | B106: INTERFACE PRINT BARCODE | C106: Billy, Baim, Budi | E106: 46023 | F106: =IF(ISBLANK(E106)," - ",IF(G106=0,E106,E106+G106-1)) -> 46032 | G106: 10 | H106: 0 | I106: 6
A107: =IF(ISERROR(VALUE(SUBSTITUTE(prevWBS,".",""))),"0.1",IF(ISERROR(FIND("`",SUBSTITUTE(prevWBS,".","`",1))),prevWBS&".1",LEFT(prevWBS,FIND("`",SUBSTITUTE(prevWBS,".","`",1)))&IF(ISERROR(FIND("`",SUBSTITUTE(prevWBS,".","`",2))),VALUE(RIGHT(prevWBS,LEN(prevWBS)-FIND("`",SUBSTITUTE(prevWBS,".","`",1))))+1,VALUE(MID(prevWBS,FIND("`",SUBSTITUTE(prevWBS,".","`",1))+1,(FIND("`",SUBSTITUTE(prevWBS,".","`",2))-FIND("`",SUBSTITUTE(prevWBS,".","`",1))-1)))+1))) -> 2.3 | B107: INTERFACE PRINT BARCODE BANYAK LIST KARTON | C107: Billy, Baim | E107: 46034 | F107: =IF(ISBLANK(E107)," - ",IF(G107=0,E107,E107+G107-1)) -> 46038 | G107: 5 | H107: 0 | I107: 5
A108: =IF(ISERROR(VALUE(SUBSTITUTE(prevWBS,".",""))),"1",IF(ISERROR(FIND("`",SUBSTITUTE(prevWBS,".","`",1))),TEXT(VALUE(prevWBS)+1,"#"),TEXT(VALUE(LEFT(prevWBS,FIND("`",SUBSTITUTE(prevWBS,".","`",1))-1))+1,"#"))) -> 3 | B108: Forms | F108: =IF(ISBLANK(E108)," - ",IF(G108=0,E108,E108+G108-1)) -> - | I108: =IF(OR(F108=0,E108=0)," - ",NETWORKDAYS(E108,F108)) -> -
A109: =IF(ISERROR(VALUE(SUBSTITUTE(prevWBS,".",""))),"0.1",IF(ISERROR(FIND("`",SUBSTITUTE(prevWBS,".","`",1))),prevWBS&".1",LEFT(prevWBS,FIND("`",SUBSTITUTE(prevWBS,".","`",1)))&IF(ISERROR(FIND("`",SUBSTITUTE(prevWBS,".","`",2))),VALUE(RIGHT(prevWBS,LEN(prevWBS)-FIND("`",SUBSTITUTE(prevWBS,".","`",1))))+1,VALUE(MID(prevWBS,FIND("`",SUBSTITUTE(prevWBS,".","`",1))+1,(FIND("`",SUBSTITUTE(prevWBS,".","`",2))-FIND("`",SUBSTITUTE(prevWBS,".","`",1))-1)))+1))) -> 3.1 | B109: Form Transfer Posting (ZSCMF001) | C109: Billy, Budi | E109: 46041 | F109: =IF(ISBLANK(E109)," - ",IF(G109=0,E109,E109+G109-1)) -> 46044 | G109: 4 | H109: 0 | I109: 4
A110: =IF(ISERROR(VALUE(SUBSTITUTE(prevWBS,".",""))),"0.1",IF(ISERROR(FIND("`",SUBSTITUTE(prevWBS,".","`",1))),prevWBS&".1",LEFT(prevWBS,FIND("`",SUBSTITUTE(prevWBS,".","`",1)))&IF(ISERROR(FIND("`",SUBSTITUTE(prevWBS,".","`",2))),VALUE(RIGHT(prevWBS,LEN(prevWBS)-FIND("`",SUBSTITUTE(prevWBS,".","`",1))))+1,VALUE(MID(prevWBS,FIND("`",SUBSTITUTE(prevWBS,".","`",1))+1,(FIND("`",SUBSTITUTE(prevWBS,".","`",2))-FIND("`",SUBSTITUTE(prevWBS,".","`",1))-1)))+1))) -> 3.2 | B110: Form Purchase Order (ZSCMF002) | C110: Billy, Baim | E110: 46041 | F110: =IF(ISBLANK(E110)," - ",IF(G110=0,E110,E110+G110-1)) -> 46044 | G110: 4 | H110: 0 | I110: 4
A111: =IF(ISERROR(VALUE(SUBSTITUTE(prevWBS,".",""))),"0.1",IF(ISERROR(FIND("`",SUBSTITUTE(prevWBS,".","`",1))),prevWBS&".1",LEFT(prevWBS,FIND("`",SUBSTITUTE(prevWBS,".","`",1)))&IF(ISERROR(FIND("`",SUBSTITUTE(prevWBS,".","`",2))),VALUE(RIGHT(prevWBS,LEN(prevWBS)-FIND("`",SUBSTITUTE(prevWBS,".","`",1))))+1,VALUE(MID(prevWBS,FIND("`",SUBSTITUTE(prevWBS,".","`",1))+1,(FIND("`",SUBSTITUTE(prevWBS,".","`",2))-FIND("`",SUBSTITUTE(prevWBS,".","`",1))-1)))+1))) -> 3.3 | B111: Form Good Receipt (ZSCMF003) | C111: Baim | E111: 46045 | F111: =IF(ISBLANK(E111)," - ",IF(G111=0,E111,E111+G111-1)) -> 46050 | G111: 6 | H111: 0 | I111: 4
A112: =IF(ISERROR(VALUE(SUBSTITUTE(prevWBS,".",""))),"0.1",IF(ISERROR(FIND("`",SUBSTITUTE(prevWBS,".","`",1))),prevWBS&".1",LEFT(prevWBS,FIND("`",SUBSTITUTE(prevWBS,".","`",1)))&IF(ISERROR(FIND("`",SUBSTITUTE(prevWBS,".","`",2))),VALUE(RIGHT(prevWBS,LEN(prevWBS)-FIND("`",SUBSTITUTE(prevWBS,".","`",1))))+1,VALUE(MID(prevWBS,FIND("`",SUBSTITUTE(prevWBS,".","`",1))+1,(FIND("`",SUBSTITUTE(prevWBS,".","`",2))-FIND("`",SUBSTITUTE(prevWBS,".","`",1))-1)))+1))) -> 3.4 | B112: Form Good Issue (ZSCMF004) | C112: Baim | E112: 46051 | F112: =IF(ISBLANK(E112)," - ",IF(G112=0,E112,E112+G112-1)) -> 46056 | G112: 6 | H112: 0 | I112: 4
...

Sheet j
A1: RICEF BY LEUWITEX ( update 17 Maret 2026 )
B4: Project Start Date | C4: 45986 | G4: Display Week | H4: 1 | K4: ="Week "&(K6-($C$4-WEEKDAY($C$4,1)+2))/7+1 -> Week 1 | R4: ="Week "&(R6-($C$4-WEEKDAY($C$4,1)+2))/7+1 -> Week 2 | Y4: ="Week "&(Y6-($C$4-WEEKDAY($C$4,1)+2))/7+1 -> Week 3 | AF4: ="Week "&(AF6-($C$4-WEEKDAY($C$4,1)+2))/7+1 -> Week 4 | AM4: ="Week "&(AM6-($C$4-WEEKDAY($C$4,1)+2))/7+1 -> Week 5 | AT4: ="Week "&(AT6-($C$4-WEEKDAY($C$4,1)+2))/7+1 -> Week 6 | BA4: ="Week "&(BA6-($C$4-WEEKDAY($C$4,1)+2))/7+1 -> Week 7 | BH4: ="Week "&(BH6-($C$4-WEEKDAY($C$4,1)+2))/7+1 -> Week 8
B5: Project Lead | C5: Billy | K5: =K6 -> 45985 | R5: =R6 -> 45992 | Y5: =Y6 -> 45999 | AF5: =AF6 -> 46006 | AM5: =AM6 -> 46013 | AT5: =AT6 -> 46020 | BA5: =BA6 -> 46027 | BH5: =BH6 -> 46034
K6: =C4-WEEKDAY(C4,1)+2+7*(H4-1) -> 45985 | L6: =K6+1 -> 45986 | M6: =L6+1 -> 45987 | N6: =M6+1 -> 45988 | O6: =N6+1 -> 45989 | P6: =O6+1 -> 45990 | Q6: =P6+1 -> 45991 | R6: =Q6+1 -> 45992 | S6: =R6+1 -> 45993 | ... BN6: =BM6+1 -> 46040
A7: WBS | B7: TASK | C7: PIC | D7: NOTES | E7: START | F7: END | G7: DAYS | H7: % DONE | I7: WORK DAYS | K7: =CHOOSE(WEEKDAY(K6,1),"S","M","T","W","T","F","S") -> M | L7: =CHOOSE(WEEKDAY(L6,1),"S","M","T","W","T","F","S") -> T | M7: =CHOOSE(WEEKDAY(M6,1),"S","M","T","W","T","F","S") -> W | N7: =CHOOSE(WEEKDAY(N6,1),"S","M","T","W","T","F","S") -> T | O7: =CHOOSE(WEEKDAY(O6,1),"S","M","T","W","T","F","S") -> F | P7: =CHOOSE(WEEKDAY(P6,1),"S","M","T","W","T","F","S") -> S | Q7: =CHOOSE(WEEKDAY(Q6,1),"S","M","T","W","T","F","S") -> S | R7: =CHOOSE(WEEKDAY(R6,1),"S","M","T","W","T","F","S") -> M | ... BN7: =CHOOSE(WEEKDAY(BN6,1),"S","M","T","W","T","F","S") -> S
A8: =IF(ISERROR(VALUE(SUBSTITUTE(prevWBS,".",""))),"1",IF(ISERROR(FIND("`",SUBSTITUTE(prevWBS,".","`",1))),TEXT(VALUE(prevWBS)+1,"#"),TEXT(VALUE(LEFT(prevWBS,FIND("`",SUBSTITUTE(prevWBS,".","`",1))-1))+1,"#"))) -> 1 | B8: SAP API development | F8: =IF(ISBLANK(E8)," - ",IF(G8=0,E8,E8+G8-1)) -> - | I8: =IF(OR(F8=0,E8=0)," - ",NETWORKDAYS(E8,F8)) -> -
A9: =IF(ISERROR(VALUE(SUBSTITUTE(prevWBS,".",""))),"0.1",IF(ISERROR(FIND("`",SUBSTITUTE(prevWBS,".","`",1))),prevWBS&".1",LEFT(prevWBS,FIND("`",SUBSTITUTE(prevWBS,".","`",1)))&IF(ISERROR(FIND("`",SUBSTITUTE(prevWBS,".","`",2))),VALUE(RIGHT(prevWBS,LEN(prevWBS)-FIND("`",SUBSTITUTE(prevWBS,".","`",1))))+1,VALUE(MID(prevWBS,FIND("`",SUBSTITUTE(prevWBS,".","`",1))+1,(FIND("`",SUBSTITUTE(prevWBS,".","`",2))-FIND("`",SUBSTITUTE(prevWBS,".","`",1))-1)))+1))) -> 1.1 | B9: INSTALL ECLIPSE, ADOBE LIFECYCLE DI PC | C9: Baim, Budi | E9: 45987 | F9: =IF(ISBLANK(E9)," - ",IF(G9=0,E9,E9+G9-1)) -> 45987 | G9: 1 | H9: 1 | I9: =IF(OR(F9=0,E9=0)," - ",NETWORKDAYS(E9,F9)) -> 1
A10: =IF(ISERROR(VALUE(SUBSTITUTE(prevWBS,".",""))),"0.1",IF(ISERROR(FIND("`",SUBSTITUTE(prevWBS,".","`",1))),prevWBS&".1",LEFT(prevWBS,FIND("`",SUBSTITUTE(prevWBS,".","`",1)))&IF(ISERROR(FIND("`",SUBSTITUTE(prevWBS,".","`",2))),VALUE(RIGHT(prevWBS,LEN(prevWBS)-FIND("`",SUBSTITUTE(prevWBS,".","`",1))))+1,VALUE(MID(prevWBS,FIND("`",SUBSTITUTE(prevWBS,".","`",1))+1,(FIND("`",SUBSTITUTE(prevWBS,".","`",2))-FIND("`",SUBSTITUTE(prevWBS,".","`",1))-1)))+1))) -> 1.2 | B10: BELAJAR KE SOLTIUS TENTANG SAP | C10: Baim, Budi | E10: 45988 | F10: =IF(ISBLANK(E10)," - ",IF(G10=0,E10,E10+G10-1)) -> 46054 | G10: 67 | H10: 0.5 | I10: =IF(OR(F10=0,E10=0)," - ",NETWORKDAYS(E10,F10)) -> 47
A11: =IF(ISERROR(VALUE(SUBSTITUTE(prevWBS,".",""))),"0.1",IF(ISERROR(FIND("`",SUBSTITUTE(prevWBS,".","`",1))),prevWBS&".1",LEFT(prevWBS,FIND("`",SUBSTITUTE(prevWBS,".","`",1)))&IF(ISERROR(FIND("`",SUBSTITUTE(prevWBS,".","`",2))),VALUE(RIGHT(prevWBS,LEN(prevWBS)-FIND("`",SUBSTITUTE(prevWBS,".","`",1))))+1,VALUE(MID(prevWBS,FIND("`",SUBSTITUTE(prevWBS,".","`",1))+1,(FIND("`",SUBSTITUTE(prevWBS,".","`",2))-FIND("`",SUBSTITUTE(prevWBS,".","`",1))-1)))+1))) -> 1.3 | B11: INTEGRASI API SAP KE PRINT BARCODE INTERNAL | C11: Baim, Budi | E11: 45995 | F11: =IF(ISBLANK(E11)," - ",IF(G11=0,E11,E11+G11-1)) -> 46001 | G11: 7 | H11: 1 | I11: =IF(OR(F11=0,E11=0)," - ",NETWORKDAYS(E11,F11)) -> 5
A12: =IF(ISERROR(VALUE(SUBSTITUTE(prevWBS,".",""))),"0.1",IF(ISERROR(FIND("`",SUBSTITUTE(prevWBS,".","`",1))),prevWBS&".1",LEFT(prevWBS,FIND("`",SUBSTITUTE(prevWBS,".","`",1)))&IF(ISERROR(FIND("`",SUBSTITUTE(prevWBS,".","`",2))),VALUE(RIGHT(prevWBS,LEN(prevWBS)-FIND("`",SUBSTITUTE(prevWBS,".","`",1))))+1,VALUE(MID(prevWBS,FIND("`",SUBSTITUTE(prevWBS,".","`",1))+1,(FIND("`",SUBSTITUTE(prevWBS,".","`",2))-FIND("`",SUBSTITUTE(prevWBS,".","`",1))-1)))+1))) -> 1.4 | B12: MAPPING IT INVENTORY | C12: Baim | E12: 46009 | F12: =IF(ISBLANK(E12)," - ",IF(G12=0,E12,E12+G12-1)) -> 46014 | G12: 6 | H12: 1 | I12: =IF(OR(F12=0,E12=0)," - ",NETWORKDAYS(E12,F12)) -> 4
A13: =IF(ISERROR(VALUE(SUBSTITUTE(prevWBS,".",""))),"0.1",IF(ISERROR(FIND("`",SUBSTITUTE(prevWBS,".","`",1))),prevWBS&".1",LEFT(prevWBS,FIND("`",SUBSTITUTE(prevWBS,".","`",1)))&IF(ISERROR(FIND("`",SUBSTITUTE(prevWBS,".","`",2))),VALUE(RIGHT(prevWBS,LEN(prevWBS)-FIND("`",SUBSTITUTE(prevWBS,".","`",1))))+1,VALUE(MID(prevWBS,FIND("`",SUBSTITUTE(prevWBS,".","`",1))+1,(FIND("`",SUBSTITUTE(prevWBS,".","`",2))-FIND("`",SUBSTITUTE(prevWBS,".","`",1))-1)))+1))) -> 1.5 | B13: BELAJAR MENDAFTARKAN API SAP | C13: Baim, Budi | E13: 46021 | F13: =IF(ISBLANK(E13)," - ",IF(G13=0,E13,E13+G13-1)) -> 46021 | G13: 1 | H13: 1 | I13: =IF(OR(F13=0,E13=0)," - ",NETWORKDAYS(E13,F13)) -> 1
A14: =IF(ISERROR(VALUE(SUBSTITUTE(prevWBS,".",""))),"0.1",IF(ISERROR(FIND("`",SUBSTITUTE(prevWBS,".","`",1))),prevWBS&".1",LEFT(prevWBS,FIND("`",SUBSTITUTE(prevWBS,".","`",1)))&IF(ISERROR(FIND("`",SUBSTITUTE(prevWBS,".","`",2))),VALUE(RIGHT(prevWBS,LEN(prevWBS)-FIND("`",SUBSTITUTE(prevWBS,".","`",1))))+1,VALUE(MID(prevWBS,FIND("`",SUBSTITUTE(prevWBS,".","`",1))+1,(FIND("`",SUBSTITUTE(prevWBS,".","`",2))-FIND("`",SUBSTITUTE(prevWBS,".","`",1))-1)))+1))) -> 1.6 | B14: MAPPING TABEL TAMBAHAN BEA CUKAI | C14: Baim | E14: 46021 | F14: =IF(ISBLANK(E14)," - ",IF(G14=0,E14,E14+G14-1)) -> 46030 | G14: 10 | H14: 1 | I14: =IF(OR(F14=0,E14=0)," - ",NETWORKDAYS(E14,F14)) -> 8
A15: =IF(ISERROR(VALUE(SUBSTITUTE(prevWBS,".",""))),"0.1",IF(ISERROR(FIND("`",SUBSTITUTE(prevWBS,".","`",1))),prevWBS&".1",LEFT(prevWBS,FIND("`",SUBSTITUTE(prevWBS,".","`",1)))&IF(ISERROR(FIND("`",SUBSTITUTE(prevWBS,".","`",2))),VALUE(RIGHT(prevWBS,LEN(prevWBS)-FIND("`",SUBSTITUTE(prevWBS,".","`",1))))+1,VALUE(MID(prevWBS,FIND("`",SUBSTITUTE(prevWBS,".","`",1))+1,(FIND("`",SUBSTITUTE(prevWBS,".","`",2))-FIND("`",SUBSTITUTE(prevWBS,".","`",1))-1)))+1))) -> 1.7 | B15: SIT | C15: Baim, Budi | E15: 46028 | F15: =IF(ISBLANK(E15)," - ",IF(G15=0,E15,E15+G15-1)) -> 46030 | G15: 3 | H15: 1 | I15: =IF(OR(F15=0,E15=0)," - ",NETWORKDAYS(E15,F15)) -> 3
A16: =IF(ISERROR(VALUE(SUBSTITUTE(prevWBS,".",""))),"0.1",IF(ISERROR(FIND("`",SUBSTITUTE(prevWBS,".","`",1))),prevWBS&".1",LEFT(prevWBS,FIND("`",SUBSTITUTE(prevWBS,".","`",1)))&IF(ISERROR(FIND("`",SUBSTITUTE(prevWBS,".","`",2))),VALUE(RIGHT(prevWBS,LEN(prevWBS)-FIND("`",SUBSTITUTE(prevWBS,".","`",1))))+1,VALUE(MID(prevWBS,FIND("`",SUBSTITUTE(prevWBS,".","`",1))+1,(FIND("`",SUBSTITUTE(prevWBS,".","`",2))-FIND("`",SUBSTITUTE(prevWBS,".","`",1))-1)))+1))) -> 1.8 | B16: INTEGRASI API SAP UNTUK BEA CUKAI | C16: Baim, Budi, Jali, Star | E16: 46031 | F16: =IF(ISBLANK(E16)," - ",IF(G16=0,E16,E16+G16-1)) -> 46040 | G16: 10 | H16: 0.5 | I16: =IF(OR(F16=0,E16=0)," - ",NETWORKDAYS(E16,F16)) -> 6
A17: =IF(ISERROR(VALUE(SUBSTITUTE(prevWBS,".",""))),"0.1",IF(ISERROR(FIND("`",SUBSTITUTE(prevWBS,".","`",1))),prevWBS&".1",LEFT(prevWBS,FIND("`",SUBSTITUTE(prevWBS,".","`",1)))&IF(ISERROR(FIND("`",SUBSTITUTE(prevWBS,".","`",2))),VALUE(RIGHT(prevWBS,LEN(prevWBS)-FIND("`",SUBSTITUTE(prevWBS,".","`",1))))+1,VALUE(MID(prevWBS,FIND("`",SUBSTITUTE(prevWBS,".","`",1))+1,(FIND("`",SUBSTITUTE(prevWBS,".","`",2))-FIND("`",SUBSTITUTE(prevWBS,".","`",1))-1)))+1))) -> 1.9 | B17: BELAJAR MENGEDIT FORM SAP | C17: Baim, Budi | E17: 46030 | F17: =IF(ISBLANK(E17)," - ",IF(G17=0,E17,E17+G17-1)) -> 46030 | G17: 1 | H17: 1 | I17: =IF(OR(F17=0,E17=0)," - ",NETWORKDAYS(E17,F17)) -> 1
A18: =IF(ISERROR(VALUE(SUBSTITUTE(prevWBS,".",""))),"0.1",IF(ISERROR(FIND("`",SUBSTITUTE(prevWBS,".","`",1))),prevWBS&".1",LEFT(prevWBS,FIND("`",SUBSTITUTE(prevWBS,".","`",1)))&IF(ISERROR(FIND("`",SUBSTITUTE(prevWBS,".","`",2))),VALUE(RIGHT(prevWBS,LEN(prevWBS)-FIND("`",SUBSTITUTE(prevWBS,".","`",1))))+1,VALUE(MID(prevWBS,FIND("`",SUBSTITUTE(prevWBS,".","`",1))+1,(FIND("`",SUBSTITUTE(prevWBS,".","`",2))-FIND("`",SUBSTITUTE(prevWBS,".","`",1))-1)))+1))) -> 1.10 | B18: KUT SAP BAGIAN MASTER DATA MM | C18: Baim | E18: 46037 | F18: =IF(ISBLANK(E18)," - ",IF(G18=0,E18,E18+G18-1)) -> 46038 | G18: 2 | H18: 1 | I18: =IF(OR(F18=0,E18=0)," - ",NETWORKDAYS(E18,F18)) -> 2
A19: =IF(ISERROR(VALUE(SUBSTITUTE(prevWBS,".",""))),"0.1",IF(ISERROR(FIND("`",SUBSTITUTE(prevWBS,".","`",1))),prevWBS&".1",LEFT(prevWBS,FIND("`",SUBSTITUTE(prevWBS,".","`",1)))&IF(ISERROR(FIND("`",SUBSTITUTE(prevWBS,".","`",2))),VALUE(RIGHT(prevWBS,LEN(prevWBS)-FIND("`",SUBSTITUTE(prevWBS,".","`",1))))+1,VALUE(MID(prevWBS,FIND("`",SUBSTITUTE(prevWBS,".","`",1))+1,(FIND("`",SUBSTITUTE(prevWBS,".","`",2))-FIND("`",SUBSTITUTE(prevWBS,".","`",1))-1)))+1))) -> 1.11 | B19: KUT SAP BAGIAN MASTER DATA SD dan FICO | C19: Budi | E19: 46037 | F19: =IF(ISBLANK(E19)," - ",IF(G19=0,E19,E19+G19-1)) -> 46038 | G19: 2 | H19: 1 | I19: =IF(OR(F19=0,E19=0)," - ",NETWORKDAYS(E19,F19)) -> 2
A20: =IF(ISERROR(VALUE(SUBSTITUTE(prevWBS,".",""))),"0.1",IF(ISERROR(FIND("`",SUBSTITUTE(prevWBS,".","`",1))),prevWBS&".1",LEFT(prevWBS,FIND("`",SUBSTITUTE(prevWBS,".","`",1)))&IF(ISERROR(FIND("`",SUBSTITUTE(prevWBS,".","`",2))),VALUE(RIGHT(prevWBS,LEN(prevWBS)-FIND("`",SUBSTITUTE(prevWBS,".","`",1))))+1,VALUE(MID(prevWBS,FIND("`",SUBSTITUTE(prevWBS,".","`",1))+1,(FIND("`",SUBSTITUTE(prevWBS,".","`",2))-FIND("`",SUBSTITUTE(prevWBS,".","`",1))-1)))+1))) -> 1.12 | B20: Modifikasi Form Invoice (Barang Bekas, Avfal, BS, Maklon, Masker) | C20: Baim | E20: 46032 | F20: =IF(ISBLANK(E20)," - ",IF(G20=0,E20,E20+G20-1)) -> 46043 | G20: 12 | H20: 1 | I20: =IF(OR(F20=0,E20=0)," - ",NETWORKDAYS(E20,F20)) -> 8
... A23: =IF(ISERROR(VALUE(SUBSTITUTE(prevWBS,".",""))),"0.1",IF(ISERROR(FIND("`",SUBSTITUTE(prevWBS,".","`",1))),prevWBS&".1",LEFT(prevWBS,FIND("`",SUBSTITUTE(prevWBS,".","`",1)))&IF(ISERROR(FIND("`",SUBSTITUTE(prevWBS,".","`",2))),VALUE(RIGHT(prevWBS,LEN(prevWBS)-FIND("`",SUBSTITUTE(prevWBS,".","`",1))))+1,VALUE(MID(prevWBS,FIND("`",SUBSTITUTE(prevWBS,".","`",1))+1,(FIND("`",SUBSTITUTE(prevWBS,".","`",2))-FIND("`",SUBSTITUTE(prevWBS,".","`",1))-1)))+1))) -> 1.15 | B23: Buat UI penarikan data dari API dan insert data Material | C23: Budi | E23: 46056 | F23: =IF(ISBLANK(E23)," - ",IF(G23=0,E23,E23+G23-1)) -> 46057 | G23: 2 | H23: 1 | I23: =IF(OR(F23=0,E23=0)," - ",NETWORKDAYS(E23,F23)) -> 2
A24: =IF(ISERROR(VALUE(SUBSTITUTE(prevWBS,".",""))),"0.1",IF(ISERROR(FIND("`",SUBSTITUTE(prevWBS,".","`",1))),prevWBS&".1",LEFT(prevWBS,FIND("`",SUBSTITUTE(prevWBS,".","`",1)))&IF(ISERROR(FIND("`",SUBSTITUTE(prevWBS,".","`",2))),VALUE(RIGHT(prevWBS,LEN(prevWBS)-FIND("`",SUBSTITUTE(prevWBS,".","`",1))))+1,VALUE(MID(prevWBS,FIND("`",SUBSTITUTE(prevWBS,".","`",1))+1,(FIND("`",SUBSTITUTE(prevWBS,".","`",2))-FIND("`",SUBSTITUTE(prevWBS,".","`",1))-1)))+1))) -> 1.16 | B24: Buat UI penarikan data dari API dan insert data Warehouse | C24: Budi | E24: =F22+1 -> 46058 | F24: =IF(ISBLANK(E24)," - ",IF(G24=0,E24,E24+G24-1)) -> 46059 | G24: 2 | H24: 1 | I24: =IF(OR(F24=0,E24=0)," - ",NETWORKDAYS(E24,F24)) -> 2
A25: =IF(ISERROR(VALUE(SUBSTITUTE(prevWBS,".",""))),"0.1",IF(ISERROR(FIND("`",SUBSTITUTE(prevWBS,".","`",1))),prevWBS&".1",LEFT(prevWBS,FIND("`",SUBSTITUTE(prevWBS,".","`",1)))&IF(ISERROR(FIND("`",SUBSTITUTE(prevWBS,".","`",2))),VALUE(RIGHT(prevWBS,LEN(prevWBS)-FIND("`",SUBSTITUTE(prevWBS,".","`",1))))+1,VALUE(MID(prevWBS,FIND("`",SUBSTITUTE(prevWBS,".","`",1))+1,(FIND("`",SUBSTITUTE(prevWBS,".","`",2))-FIND("`",SUBSTITUTE(prevWBS,".","`",1))-1)))+1))) -> 1.17 | B25: Buat UI penarikan data dari API dan insert data Asset | C25: Baim | E25: =F22+1 -> 46058 | F25: =IF(ISBLANK(E25)," - ",IF(G25=0,E25,E25+G25-1)) -> 46059 | G25: 2 | H25: 1 | I25: =IF(OR(F25=0,E25=0)," - ",NETWORKDAYS(E25,F25)) -> 2
A26: =IF(ISERROR(VALUE(SUBSTITUTE(prevWBS,".",""))),"0.1",IF(ISERROR(FIND("`",SUBSTITUTE(prevWBS,".","`",1))),prevWBS&".1",LEFT(prevWBS,FIND("`",SUBSTITUTE(prevWBS,".","`",1)))&IF(ISERROR(FIND("`",SUBSTITUTE(prevWBS,".","`",2))),VALUE(RIGHT(prevWBS,LEN(prevWBS)-FIND("`",SUBSTITUTE(prevWBS,".","`",1))))+1,VALUE(MID(prevWBS,FIND("`",SUBSTITUTE(prevWBS,".","`",1))+1,(FIND("`",SUBSTITUTE(prevWBS,".","`",2))-FIND("`",SUBSTITUTE(prevWBS,".","`",1))-1)))+1))) -> 1.18 | B26: Buat UI penarikan data dari API dan insert data Invoice | C26: Budi | E26: =E23+1 -> 46057 | F26: =IF(ISBLANK(E26)," - ",IF(G26=0,E26,E26+G26-1)) -> 46058 | G26: 2 | H26: 1 | I26: =IF(OR(F26=0,E26=0)," - ",NETWORKDAYS(E26,F26)) -> 2
A27: =IF(ISERROR(VALUE(SUBSTITUTE(prevWBS,".",""))),"0.1",IF(ISERROR(FIND("`",SUBSTITUTE(prevWBS,".","`",1))),prevWBS&".1",LEFT(prevWBS,FIND("`",SUBSTITUTE(prevWBS,".","`",1)))&IF(ISERROR(FIND("`",SUBSTITUTE(prevWBS,".","`",2))),VALUE(RIGHT(prevWBS,LEN(prevWBS)-FIND("`",SUBSTITUTE(prevWBS,".","`",1))))+1,VALUE(MID(prevWBS,FIND("`",SUBSTITUTE(prevWBS,".","`",1))+1,(FIND("`",SUBSTITUTE(prevWBS,".","`",2))-FIND("`",SUBSTITUTE(prevWBS,".","`",1))-1)))+1))) -> 1.19 | B27: Buat UI penarikan data dari API dan insert data Supplier | C27: Baim | E27: =F23+1 -> 46058 | F27: =IF(ISBLANK(E27)," - ",IF(G27=0,E27,E27+G27-1)) -> 46059 | G27: 2 | H27: 1 | I27: =IF(OR(F27=0,E27=0)," - ",NETWORKDAYS(E27,F27)) -> 2
A28: =IF(ISERROR(VALUE(SUBSTITUTE(prevWBS,".",""))),"0.1",IF(ISERROR(FIND("`",SUBSTITUTE(prevWBS,".","`",1))),prevWBS&".1",LEFT(prevWBS,FIND("`",SUBSTITUTE(prevWBS,".","`",1)))&IF(ISERROR(FIND("`",SUBSTITUTE(prevWBS,".","`",2))),VALUE(RIGHT(prevWBS,LEN(prevWBS)-FIND("`",SUBSTITUTE(prevWBS,".","`",1))))+1,VALUE(MID(prevWBS,FIND("`",SUBSTITUTE(prevWBS,".","`",1))+1,(FIND("`",SUBSTITUTE(prevWBS,".","`",2))-FIND("`",SUBSTITUTE(prevWBS,".","`",1))-1)))+1))) -> 1.20 | B28: Buat UI penarikan data dari API dan insert data Master Customer | C28: Budi | E28: =F24+1 -> 46060 | F28: =IF(ISBLANK(E28)," - ",IF(G28=0,E28,E28+G28-1)) -> 46063 | G28: 4 | H28: 1 | I28: =IF(OR(F28=0,E28=0)," - ",NETWORKDAYS(E28,F28)) -> 2
A29: =IF(ISERROR(VALUE(SUBSTITUTE(prevWBS,".",""))),"0.1",IF(ISERROR(FIND("`",SUBSTITUTE(prevWBS,".","`",1))),prevWBS&".1",LEFT(prevWBS,FIND("`",SUBSTITUTE(prevWBS,".","`",1)))&IF(ISERROR(FIND("`",SUBSTITUTE(prevWBS,".","`",2))),VALUE(RIGHT(prevWBS,LEN(prevWBS)-FIND("`",SUBSTITUTE(prevWBS,".","`",1))))+1,VALUE(MID(prevWBS,FIND("`",SUBSTITUTE(prevWBS,".","`",1))+1,(FIND("`",SUBSTITUTE(prevWBS,".","`",2))-FIND("`",SUBSTITUTE(prevWBS,".","`",1))-1)))+1))) -> 1.21 | B29: Buat UI penarikan data dari API dan insert data PO | C29: Baim | E29: =F24+1 -> 46060 | F29: =IF(ISBLANK(E29)," - ",IF(G29=0,E29,E29+G29-1)) -> 46063 | G29: 4 | H29: 1 | I29: =IF(OR(F29=0,E29=0)," - ",NETWORKDAYS(E29,F29)) -> 2
A30: =IF(ISERROR(VALUE(SUBSTITUTE(prevWBS,".",""))),"0.1",IF(ISERROR(FIND("`",SUBSTITUTE(prevWBS,".","`",1))),prevWBS&".1",LEFT(prevWBS,FIND("`",SUBSTITUTE(prevWBS,".","`",1)))&IF(ISERROR(FIND("`",SUBSTITUTE(prevWBS,".","`",2))),VALUE(RIGHT(prevWBS,LEN(prevWBS)-FIND("`",SUBSTITUTE(prevWBS,".","`",1))))+1,VALUE(MID(prevWBS,FIND("`",SUBSTITUTE(prevWBS,".","`",1))+1,(FIND("`",SUBSTITUTE(prevWBS,".","`",2))-FIND("`",SUBSTITUTE(prevWBS,".","`",1))-1)))+1))) -> 1.22 | B30: Buat UI penarikan data dari API dan insert data Material Document | C30: Budi | E30: =F28+1 -> 46064 | F30: =IF(ISBLANK(E30)," - ",IF(G30=0,E30,E30+G30-1)) -> 46065 | G30: 2 | H30: 1 | I30: =IF(OR(F30=0,E30=0)," - ",NETWORKDAYS(E30,F30)) -> 2
A31: =IF(ISERROR(VALUE(SUBSTITUTE(prevWBS,".",""))),"0.1",IF(ISERROR(FIND("`",SUBSTITUTE(prevWBS,".","`",1))),prevWBS&".1",LEFT(prevWBS,FIND("`",SUBSTITUTE(prevWBS,".","`",1)))&IF(ISERROR(FIND("`",SUBSTITUTE(prevWBS,".","`",2))),VALUE(RIGHT(prevWBS,LEN(prevWBS)-FIND("`",SUBSTITUTE(prevWBS,".","`",1))))+1,VALUE(MID(prevWBS,FIND("`",SUBSTITUTE(prevWBS,".","`",1))+1,(FIND("`",SUBSTITUTE(prevWBS,".","`",2))-FIND("`",SUBSTITUTE(prevWBS,".","`",1))-1)))+1))) -> 1.23 | B31: Buat UI penarikan data dari API dan insert data BOM | C31: Baim | E31: =F29+1 -> 46064 | F31: =IF(ISBLANK(E31)," - ",IF(G31=0,E31,E31+G31-1)) -> 46065 | G31: 2 | H31: 1 | I31: =IF(OR(F31=0,E31=0)," - ",NETWORKDAYS(E31,F31)) -> 2
A32: =IF(ISERROR(VALUE(SUBSTITUTE(prevWBS,".",""))),"0.1",IF(ISERROR(FIND("`",SUBSTITUTE(prevWBS,".","`",1))),prevWBS&".1",LEFT(prevWBS,FIND("`",SUBSTITUTE(prevWBS,".","`",1)))&IF(ISERROR(FIND("`",SUBSTITUTE(prevWBS,".","`",2))),VALUE(RIGHT(prevWBS,LEN(prevWBS)-FIND("`",SUBSTITUTE(prevWBS,".","`",1))))+1,VALUE(MID(prevWBS,FIND("`",SUBSTITUTE(prevWBS,".","`",1))+1,(FIND("`",SUBSTITUTE(prevWBS,".","`",2))-FIND("`",SUBSTITUTE(prevWBS,".","`",1))-1)))+1))) -> 1.24 | B32: UAT | C32: Baim, Budi | E32: =F30 -> 46065 | F32: =IF(ISBLANK(E32)," - ",IF(G32=0,E32,E32+G32-1)) -> 46067 | G32: 3 | H32: 1 | I32: =IF(OR(F32=0,E32=0)," - ",NETWORKDAYS(E32,F32)) -> 2
A33: =IF(ISERROR(VALUE(SUBSTITUTE(prevWBS,".",""))),"0.1",IF(ISERROR(FIND("`",SUBSTITUTE(prevWBS,".","`",1))),prevWBS&".1",LEFT(prevWBS,FIND("`",SUBSTITUTE(prevWBS,".","`",1)))&IF(ISERROR(FIND("`",SUBSTITUTE(prevWBS,".","`",2))),VALUE(RIGHT(prevWBS,LEN(prevWBS)-FIND("`",SUBSTITUTE(prevWBS,".","`",1))))+1,VALUE(MID(prevWBS,FIND("`",SUBSTITUTE(prevWBS,".","`",1))+1,(FIND("`",SUBSTITUTE(prevWBS,".","`",2))-FIND("`",SUBSTITUTE(prevWBS,".","`",1))-1)))+1))) -> 1.25 | B33: BBK INTERN | C33: Budi | E33: =F32+1 -> 46068 | F33: =IF(ISBLANK(E33)," - ",IF(G33=0,E33,E33+G33-1)) -> 46072 | G33: 5 | H33: 1 | I33: =IF(OR(F33=0,E33=0)," - ",NETWORKDAYS(E33,F33)) -> 4
A34: =IF(ISERROR(VALUE(SUBSTITUTE(prevWBS,".",""))),"0.1",IF(ISERROR(FIND("`",SUBSTITUTE(prevWBS,".","`",1))),prevWBS&".1",LEFT(prevWBS,FIND("`",SUBSTITUTE(prevWBS,".","`",1)))&IF(ISERROR(FIND("`",SUBSTITUTE(prevWBS,".","`",2))),VALUE(RIGHT(prevWBS,LEN(prevWBS)-FIND("`",SUBSTITUTE(prevWBS,".","`",1))))+1,VALUE(MID(prevWBS,FIND("`",SUBSTITUTE(prevWBS,".","`",1))+1,(FIND("`",SUBSTITUTE(prevWBS,".","`",2))-FIND("`",SUBSTITUTE(prevWBS,".","`",1))-1)))+1))) -> 1.26 | B34: LAPORAN SURAT JALAN (P) | C34: Baim | E34: =F32+1 -> 46068 | F34: =IF(ISBLANK(E34)," - ",IF(G34=0,E34,E34+G34-1)) -> 46072 | G34: 5 | H34: 0.8 | I34: =IF(OR(F34=0,E34=0)," - ",NETWORKDAYS(E34,F34)) -> 4
A35: =IF(ISERROR(VALUE(SUBSTITUTE(prevWBS,".",""))),"0.1",IF(ISERROR(FIND("`",SUBSTITUTE(prevWBS,".","`",1))),prevWBS&".1",LEFT(prevWBS,FIND("`",SUBSTITUTE(prevWBS,".","`",1)))&IF(ISERROR(FIND("`",SUBSTITUTE(prevWBS,".","`",2))),VALUE(RIGHT(prevWBS,LEN(prevWBS)-FIND("`",SUBSTITUTE(prevWBS,".","`",1))))+1,VALUE(MID(prevWBS,FIND("`",SUBSTITUTE(prevWBS,".","`",1))+1,(FIND("`",SUBSTITUTE(prevWBS,".","`",2))-FIND("`",SUBSTITUTE(prevWBS,".","`",1))-1)))+1))) -> 1.27 | B35: DETAIL LIST KARTON PER RAK | C35: Star | E35: =F33+1 -> 46073 | F35: =IF(ISBLANK(E35)," - ",IF(G35=0,E35,E35+G35-1)) -> 46076 | G35: 4 | H35: 1 | I35: =IF(OR(F35=0,E35=0)," - ",NETWORKDAYS(E35,F35)) -> 2
A36: =IF(ISERROR(VALUE(SUBSTITUTE(prevWBS,".",""))),"0.1",IF(ISERROR(FIND("`",SUBSTITUTE(prevWBS,".","`",1))),prevWBS&".1",LEFT(prevWBS,FIND("`",SUBSTITUTE(prevWBS,".","`",1)))&IF(ISERROR(FIND("`",SUBSTITUTE(prevWBS,".","`",2))),VALUE(RIGHT(prevWBS,LEN(prevWBS)-FIND("`",SUBSTITUTE(prevWBS,".","`",1))))+1,VALUE(MID(prevWBS,FIND("`",SUBSTITUTE(prevWBS,".","`",1))+1,(FIND("`",SUBSTITUTE(prevWBS,".","`",2))-FIND("`",SUBSTITUTE(prevWBS,".","`",1))-1)))+1))) -> 1.28 | B36: LAPORAN GUDANG PACKING LEAD TIME | C36: Baim | E36: =F34+1 -> 46073 | F36: =IF(ISBLANK(E36)," - ",IF(G36=0,E36,E36+G36-1)) -> 46076 | G36: 4 | H36: 1 | I36: =IF(OR(F36=0,E36=0)," - ",NETWORKDAYS(E36,F36)) -> 2
A37: =IF(ISERROR(VALUE(SUBSTITUTE(prevWBS,".",""))),"0.1",IF(ISERROR(FIND("`",SUBSTITUTE(prevWBS,".","`",1))),prevWBS&".1",LEFT(prevWBS,FIND("`",SUBSTITUTE(prevWBS,".","`",1)))&IF(ISERROR(FIND("`",SUBSTITUTE(prevWBS,".","`",2))),VALUE(RIGHT(prevWBS,LEN(prevWBS)-FIND("`",SUBSTITUTE(prevWBS,".","`",1))))+1,VALUE(MID(prevWBS,FIND("`",SUBSTITUTE(prevWBS,".","`",1))+1,(FIND("`",SUBSTITUTE(prevWBS,".","`",2))-FIND("`",SUBSTITUTE(prevWBS,".","`",1))-1)))+1))) -> 1.29 | B37: MOVING HISTORY PER LIST KARTON | C37: Star | E37: =F35+1 -> 46077 | F37: =IF(ISBLANK(E37)," - ",IF(G37=0,E37,E37+G37-1)) -> 46078 | G37: 2 | H37: 1 | I37: =IF(OR(F37=0,E37=0)," - ",NETWORKDAYS(E37,F37)) -> 2
A38: =IF(ISERROR(VALUE(SUBSTITUTE(prevWBS,".",""))),"0.1",IF(ISERROR(FIND("`",SUBSTITUTE(prevWBS,".","`",1))),prevWBS&".1",LEFT(prevWBS,FIND("`",SUBSTITUTE(prevWBS,".","`",1)))&IF(ISERROR(FIND("`",SUBSTITUTE(prevWBS,".","`",2))),VALUE(RIGHT(prevWBS,LEN(prevWBS)-FIND("`",SUBSTITUTE(prevWBS,".","`",1))))+1,VALUE(MID(prevWBS,FIND("`",SUBSTITUTE(prevWBS,".","`",1))+1,(FIND("`",SUBSTITUTE(prevWBS,".","`",2))-FIND("`",SUBSTITUTE(prevWBS,".","`",1))-1)))+1))) -> 1.30 | B38: DASHBOARD LAYOUT PER BIN | C38: Budi | E38: =F36+1 -> 46077 | F38: =IF(ISBLANK(E38)," - ",IF(G38=0,E38,E38+G38-1)) -> 46078 | G38: 2 | H38: 0 | I38: =IF(OR(F38=0,E38=0)," - ",NETWORKDAYS(E38,F38)) -> 2
A39: =IF(ISERROR(VALUE(SUBSTITUTE(prevWBS,".",""))),"0.1",IF(ISERROR(FIND("`",SUBSTITUTE(prevWBS,".","`",1))),prevWBS&".1",LEFT(prevWBS,FIND("`",SUBSTITUTE(prevWBS,".","`",1)))&IF(ISERROR(FIND("`",SUBSTITUTE(prevWBS,".","`",2))),VALUE(RIGHT(prevWBS,LEN(prevWBS)-FIND("`",SUBSTITUTE(prevWBS,".","`",1))))+1,VALUE(MID(prevWBS,FIND("`",SUBSTITUTE(prevWBS,".","`",1))+1,(FIND("`",SUBSTITUTE(prevWBS,".","`",2))-FIND("`",SUBSTITUTE(prevWBS,".","`",1))-1)))+1))) -> 1.31 | B39: LAPORAN SURAT JALAN SLOC | C39: Star, Baim | E39: =F37+1 -> 46079 | F39: =IF(ISBLANK(E39)," - ",IF(G39=0,E39,E39+G39-1)) -> 46080 | G39: 2 | H39: 0.8 | I39: =IF(OR(F39=0,E39=0)," - ",NETWORKDAYS(E39,F39)) -> 2
A40: =IF(ISERROR(VALUE(SUBSTITUTE(prevWBS,".",""))),"0.1",IF(ISERROR(FIND("`",SUBSTITUTE(prevWBS,".","`",1))),prevWBS&".1",LEFT(prevWBS,FIND("`",SUBSTITUTE(prevWBS,".","`",1)))&IF(ISERROR(FIND("`",SUBSTITUTE(prevWBS,".","`",2))),VALUE(RIGHT(prevWBS,LEN(prevWBS)-FIND("`",SUBSTITUTE(prevWBS,".","`",1))))+1,VALUE(MID(prevWBS,FIND("`",SUBSTITUTE(prevWBS,".","`",1))+1,(FIND("`",SUBSTITUTE(prevWBS,".","`",2))-FIND("`",SUBSTITUTE(prevWBS,".","`",1))-1)))+1))) -> 1.32 | B40: LIST KARTON PER KODE ORDER | C40: Baim | E40: =F38+1 -> 46079 | F40: =IF(ISBLANK(E40)," - ",IF(G40=0,E40,E40+G40-1)) -> 46080 | G40: 2 | H40: 1 | I40: =IF(OR(F40=0,E40=0)," - ",NETWORKDAYS(E40,F40)) -> 2
